Workbook
Name TeamStd_Price: '1_前提'!$B$8
Name TeamStd_Duration: '1_前提'!$B$9
Name Lightning_Price: '1_前提'!$B$11
Name Lightning_Duration: '1_前提'!$B$12
Name Training_Price: '1_前提'!$B$14
Name Training_Duration: '1_前提'!$B$15
Name Sat_Rate: '1_前提'!$B$22
Name Uni_Rate: '1_前提'!$B$23
Name Tim_Rate: '1_前提'!$B$24
Name Sat_Cap: '1_前提'!$B$25
Name Uni_Cap: '1_前提'!$B$26
Name Tim_Cap: '1_前提'!$B$27
Name DirectCost_PerDeal: '1_前提'!$B$28
Name Upfront_Pct: '1_前提'!$B$18
Name Collect_Months: '1_前提'!$B$19
Name Mkt_Fixed: '1_前提'!$B$30
Name Tools_Fixed: '1_前提'!$B$31
Name BackOffice_Fixed: '1_前提'!$B$32
Name Other_Fixed: '1_前提'!$B$33

Sheet 0_使い方
A1: 項目 | B1: 内容
A2: このブックでできること | B2: AIチーム開発伴走支援を主軸にした事業計画（3年・月次）を、前提→売上→原価/販管費→P&L→キャッシュ→KPI→容量まで一気通貫で計算します。
A3: 更新日 | B3: 2026-01-23（このチャットの日付）
A4: 使い方（最短） | B4: ① 1_前提 で青文字のセルだけ入力 → ② 4_売上計画 で月ごとの新規契約数を入力 → ③ 6_P&L と 8_KPI と 3_容量モデル を確認
A5: 入力ルール | B5: 青文字＝入力。黒文字＝自動計算。数式セルは触らない前提。
A6: 注意 | B6: 助成金の条件・金額は制度変更があり得るため、必ず最新の公的資料で確認してください（参考リンクは 1_前提 に記載）。

Sheet 1_前提
A1: 前提（青文字セルが入力）
A3: 期間・シナリオ
A4: 開始月 | B4: 2026-01 | C4: 月次計画の開始（YYYY-MM）
A5: 計画期間（月） | B5: 24 | C5: ヶ月 24ヶ月＝2年（生成AIサービスの寿命前提）
A6: シナリオ | B6: 2 | C6: 1=保守 / 2=標準 / 3=攻め 感度シートの置き場（現状は参考）
A7: 提供プラン（売価・期間・人数）
A8: AIチーム開発 伴走（標準）価格 | B8: 3000000 | C8: 円/社 例：3ヶ月の伴走一式（調整可）
A9: AIチーム開発 伴走（標準）期間 | B9: 3 | C9: ヶ月
A10: AIチーム開発 伴走（標準）想定参加人数 | B10: 5 | C10: 人 例：3〜5名
A11: ライトニング（1ヶ月集中）価格 | B11: 5000000 | C11: 円/社 1ヶ月短期集中。3名想定（調整可）
A12: ライトニング（1ヶ月集中）期間 | B12: 1 | C12: ヶ月
A13: ライトニング（1ヶ月集中）想定参加人数 | B13: 5 | C13: 人（上限） 3〜5名を想定。LP上は上限5名を用意。
A14: 生成AI研修（座学+実務適用）価格 | B14: 1200000 | C14: 円/回 例：1ヶ月で認識（調整可）
A15: 生成AI研修（座学+実務適用）期間 | B15: 1 | C15: ヶ月
A16: 生成AI研修（座学+実務適用）想定参加人数 | B16: 20 | C16: 人
A17: 支払い条件（キャッシュ）
A18: 契約時 前受比率 | B18: 0.5 | C18: 例：50% upfront
A19: 残額の回収期間 | B19: 3 | C19: ヶ月 残額を均等回収（概算）
A20: 入金サイト | B20: 30 | C20: 日 請求→入金まで（平均）
A21: 稼働・原価（人員コストの簡易モデル）
A22: Sat 工数単価（社内原価） | B22: 7000 | C22: 円/時間 窓口・PM/ファシリ
A23: Uni 工数単価（社内原価） | B23: 8000 | C23: 円/時間 インストラクター
A24: Tim 工数単価（社内原価） | B24: 12000 | C24: 円/時間 設計・レビュー
A25: Sat 月間稼働上限 | B25: 120 | C25: 時間/月
A26: Uni 月間稼働上限 | B26: 80 | C26: 時間/月
A27: Tim 月間稼働上限 | B27: 80 | C27: 時間/月
A28: 直接費（1案件あたり） | B28: 50000 | C28: 円/社 旅費・資料・ツール増分など
A29: 販管費（固定費）
A30: マーケ費（月額） | B30: 300000 | C30: 円/月 広告/ウェビナー/制作外注
A31: ツール費（月額） | B31: =B47*B48*B49 | C31: 円/月 200USD/人・月 × 人数 × USDJPY
A32: バックオフィス（月額） | B32: 150000 | C32: 円/月 会計/社労士/法務
A33: その他固定費（月額） | B33: 70000 | C33: 円/月 通信/雑費
A34: 営業ファネル（目安）
A35: リード→初回相談 率 | B35: 0.2
A36: 初回相談→提案 率 | B36: 0.5
A37: 提案→受注 率 | B37: 0.3
A38: 助成金（参考：顧客側の費用圧縮に影響）
A39: 事業展開等リスキリング支援コース：経費助成率（中小企業） | B39: 0.75 | C39: MHLW資料（R7.4.1版）
A40: 事業展開等リスキリング支援コース：経費助成率（中小企業以外） | B40: 0.6 | C40: 同上
A41: 事業展開等リスキリング支援コース：賃金助成（中小企業） | B41: 1000 | C41: 円/時間 1人1時間あたり
...

Sheet 2_プラン設計
A1: プラン設計（売価・工数・粗利の整合をチェック）
A3: 項目 | B3: AIチーム開発（標準） | C3: ライトニング（1ヶ月） | D3: 生成AI研修 | E3: メモ
A4: 価格 | B4: =TeamStd_Price | C4: =Lightning_Price | D4: =Training_Price | E4: 税別/税込は別途。まずは税別想定。
A5: 期間（月） | B5: =TeamStd_Duration | C5: =Lightning_Duration | D5: =Training_Duration | E5: 月次モデルの収益認識期間
A6: 想定参加人数 | B6: ='1_前提'!$B$10 | C6: ='1_前提'!$B$13 | D6: ='1_前提'!$B$16 | E6: LP上の『◯名まで』表現の基準
A7: 月あたりの提供工数（入力）
A8: Sat（窓口/PM/ファシリ） | B8: 20 | C8: 40 | D8: 6 | E8: 時間/月。MTG設定・ファシリ・議事録/タスク化も含める
A9: Uni（インストラクター） | B9: 24 | C9: 50 | D9: 10 | E9: 時間/月。現場参加・添削
A10: Tim（設計/インストラクター） | B10: 16 | C10: 40 | D10: 8 | E10: 時間/月。設計・レビュー
A11: 直接費（平均） | B11: =DirectCost_PerDeal | C11: =DirectCost_PerDeal | D11: =DirectCost_PerDeal | E11: 旅費・資料・ツール増分など（平均）
A12: 粗利計算（自動）
A13: 月次 原価（人件費） | B13: =('2_プラン設計'!$B$8*Sat_Rate)+('2_プラン設計'!$B$9*Uni_Rate)+('2_プラン設計'!$B$10*Tim_Rate) | C13: =('2_プラン設計'!$C$8*Sat_Rate)+('2_プラン設計'!$C$9*Uni_Rate)+('2_プラン設計'!$C$10*Tim_Rate) | D13: =('2_プラン設計'!$D$8*Sat_Rate)+('2_プラン設計'!$D$9*Uni_Rate)+('2_プラン設計'!$D$10*Tim_Rate) | E13: 工数×社内原価単価
A14: 月次 原価（直接費） | B14: =DirectCost_PerDeal | C14: =DirectCost_PerDeal | D14: =DirectCost_PerDeal | E14: 平均直接費（必要なら後で配賦調整）
A15: 月次 原価 合計 | B15: =B13+B14 | C15: =C13+C14 | D15: =D13+D14
A16: 月次 売上（収益認識） | B16: =B4/B5 | C16: =C4/C5 | D16: =D4/D5 | E16: 価格÷期間（月）
A17: 月次 粗利 | B17: =B16-B15 | C17: =C16-C15 | D17: =D16-D15
A18: 粗利率 | B18: =IF(B16=0,0,B17/B16) | C18: =IF(C16=0,0,C17/C16) | D18: =IF(D16=0,0,D17/D16)
A19: 参加者あたり単価（参考） | B19: =IF(B6=0,0,B4/B6) | C19: =IF(C6=0,0,C4/C6) | D19: =IF(D6=0,0,D4/D6) | E19: LP訴求用（目安）

Sheet 4_売上計画
A1: 売上計画（月次）— 新規契約数を入力すると自動計算
A3: 項目 | B3: 2026-01 | C3: 2026-02 | D3: 2026-03 | E3: 2026-04 | F3: 2026-05 | G3: 2026-06 | H3: 2026-07 | I3: 2026-08 | J3: 2026-09 | K3: 2026-10 | L3: 2026-11 | M3: 2026-12 | N3: 2027-01 | O3: 2027-02 | P3: 2027-03 | Q3: 2027-04 | R3: 2027-05 | S3: 2027-06 | T3: 2027-07 | U3: 2027-08 | V3: 2027-09 | W3: 2027-10 | X3: 2027-11 | Y3: 2027-12 | Z3: 2028-01 | AA3: 2028-02 | AB3: 2028-03 | AC3: 2028-04 | AD3: 2028-05 | AE3: 2028-06 | AF3: 2028-07 | AG3: 2028-08 | AH3: 2028-09 | AI3: 2028-10 | AJ3: 2028-11 | AK3: 2028-12
A4: 月番号 | B4: 1 | C4: 2 | D4: 3 | E4: 4 | F4: 5 | G4: 6 | H4: 7 | I4: 8 | J4: 9 | K4: 10 | L4: 11 | M4: 12 | N4: 13 | O4: 14 | P4: 15 | Q4: 16 | R4: 17 | S4: 18 | T4: 19 | U4: 20 | V4: 21 | W4: 22 | X4: 23 | Y4: 24 | Z4: 25 | AA4: 26 | AB4: 27 | AC4: 28 | AD4: 29 | AE4: 30 | AF4: 31 | AG4: 32 | AH4: 33 | AI4: 34 | AJ4: 35 | AK4: 36
A6: 入力：月ごとの新規契約数（社数/回数）
A7: 新規：AIチーム開発（標準） | B7: 0 | C7: 0 | D7: 0 | E7: 0 | F7: 0 | G7: 0 | H7: 0 | I7: 0 | J7: 0 | K7: 0 | L7: 0 | M7: 0 | N7: 0 | O7: 0 | P7: 0 | Q7: 0 | R7: 0 | S7: 0 | T7: 0 | U7: 0 | V7: 0 | W7: 0 | X7: 0 | Y7: 0 | Z7: 0 | AA7: 0 | AB7: 0 | AC7: 0 | AD7: 0 | AE7: 0 | AF7: 0 | AG7: 0 | AH7: 0 | AI7: 0 | AJ7: 0 | AK7: 0
A8: 新規：ライトニング（1ヶ月） | B8: 0 | C8: 0 | D8: 0 | E8: 0 | F8: 0 | G8: 0 | H8: 0 | I8: 0 | J8: 0 | K8: 0 | L8: 0 | M8: 0 | N8: 0 | O8: 0 | P8: 0 | Q8: 0 | R8: 0 | S8: 0 | T8: 0 | U8: 0 | V8: 0 | W8: 0 | X8: 0 | Y8: 0 | Z8: 0 | AA8: 0 | AB8: 0 | AC8: 0 | AD8: 0 | AE8: 0 | AF8: 0 | AG8: 0 | AH8: 0 | AI8: 0 | AJ8: 0 | AK8: 0
A9: 新規：生成AI研修 | B9: 0 | C9: 0 | D9: 0 | E9: 0 | F9: 0 | G9: 0 | H9: 0 | I9: 0 | J9: 0 | K9: 0 | L9: 0 | M9: 0 | N9: 0 | O9: 0 | P9: 0 | Q9: 0 | R9: 0 | S9: 0 | T9: 0 | U9: 0 | V9: 0 | W9: 0 | X9: 0 | Y9: 0 | Z9: 0 | AA9: 0 | AB9: 0 | AC9: 0 | AD9: 0 | AE9: 0 | AF9: 0 | AG9: 0 | AH9: 0 | AI9: 0 | AJ9: 0 | AK9: 0
A10: 計算：アクティブ件数（収益認識の対象）
A11: アクティブ：AIチーム開発（標準） | B11: =SUMPRODUCT(($B$4:AK$4>=B$4-TeamStd_Duration+1)*($B$4:AK$4<=B$4),$B$7:AK$7) | C11: =SUMPRODUCT(($B$4:AK$4>=C$4-TeamStd_Duration+1)*($B$4:AK$4<=C$4),$B$7:AK$7) | D11: =SUMPRODUCT(($B$4:AK$4>=D$4-TeamStd_Duration+1)*($B$4:AK$4<=D$4),$B$7:AK$7) | E11: =SUMPRODUCT(($B$4:AK$4>=E$4-TeamStd_Duration+1)*($B$4:AK$4<=E$4),$B$7:AK$7) | F11: =SUMPRODUCT(($B$4:AK$4>=F$4-TeamStd_Duration+1)*($B$4:AK$4<=F$4),$B$7:AK$7) | G11: =SUMPRODUCT(($B$4:AK$4>=G$4-TeamStd_Duration+1)*($B$4:AK$4<=G$4),$B$7:AK$7) | H11: =SUMPRODUCT(($B$4:AK$4>=H$4-TeamStd_Duration+1)*($B$4:AK$4<=H$4),$B$7:AK$7) | I11: =SUMPRODUCT(($B$4:AK$4>=I$4-TeamStd_Duration+1)*($B$4:AK$4<=I$4),$B$7:AK$7) | J11: =SUMPRODUCT(($B$4:AK$4>=J$4-TeamStd_Duration+1)*($B$4:AK$4<=J$4),$B$7:AK$7) | K11: =SUMPRODUCT(($B$4:AK$4>=K$4-TeamStd_Duration+1)*($B$4:AK$4<=K$4),$B$7:AK$7) | L11: =SUMPRODUCT(($B$4:AK$4>=L$4-TeamStd_Duration+1)*($B$4:AK$4<=L$4),$B$7:AK$7) | M11: =SUMPRODUCT(($B$4:AK$4>=M$4-TeamStd_Duration+1)*($B$4:AK$4<=M$4),$B$7:AK$7) | N11: =SUMPRODUCT(($B$4:AK$4>=N$4-TeamStd_Duration+1)*($B$4:AK$4<=N$4),$B$7:AK$7) | O11: =SUMPRODUCT(($B$4:AK$4>=O$4-TeamStd_Duration+1)*($B$4:AK$4<=O$4),$B$7:AK$7) | P11: =SUMPRODUCT(($B$4:AK$4>=P$4-TeamStd_Duration+1)*($B$4:AK$4<=P$4),$B$7:AK$7) | Q11: =SUMPRODUCT(($B$4:AK$4>=Q$4-TeamStd_Duration+1)*($B$4:AK$4<=Q$4),$B$7:AK$7) | R11: =SUMPRODUCT(($B$4:AK$4>=R$4-TeamStd_Duration+1)*($B$4:AK$4<=R$4),$B$7:AK$7) | S11: =SUMPRODUCT(($B$4:AK$4>=S$4-TeamStd_Duration+1)*($B$4:AK$4<=S$4),$B$7:AK$7) | T11: =SUMPRODUCT(($B$4:AK$4>=T$4-TeamStd_Duration+1)*($B$4:AK$4<=T$4),$B$7:AK$7) | U11: =SUMPRODUCT(($B$4:AK$4>=U$4-TeamStd_Duration+1)*($B$4:AK$4<=U$4),$B$7:AK$7) | V11: =SUMPRODUCT(($B$4:AK$4>=V$4-TeamStd_Duration+1)*($B$4:AK$4<=V$4),$B$7:AK$7) | W11: =SUMPRODUCT(($B$4:AK$4>=W$4-TeamStd_Duration+1)*($B$4:AK$4<=W$4),$B$7:AK$7) | X11: =SUMPRODUCT(($B$4:AK$4>=X$4-TeamStd_Duration+1)*($B$4:AK$4<=X$4),$B$7:AK$7) | Y11: =SUMPRODUCT(($B$4:AK$4>=Y$4-TeamStd_Duration+1)*($B$4:AK$4<=Y$4),$B$7:AK$7) | Z11: =SUMPRODUCT(($B$4:AK$4>=Z$4-TeamStd_Duration+1)*($B$4:AK$4<=Z$4),$B$7:AK$7) | AA11: =SUMPRODUCT(($B$4:AK$4>=AA$4-TeamStd_Duration+1)*($B$4:AK$4<=AA$4),$B$7:AK$7) | AB11: =SUMPRODUCT(($B$4:AK$4>=AB$4-TeamStd_Duration+1)*($B$4:AK$4<=AB$4),$B$7:AK$7) | AC11: =SUMPRODUCT(($B$4:AK$4>=AC$4-TeamStd_Duration+1)*($B$4:AK$4<=AC$4),$B$7:AK$7) | AD11: =SUMPRODUCT(($B$4:AK$4>=AD$4-TeamStd_Duration+1)*($B$4:AK$4<=AD$4),$B$7:AK$7) | AE11: =SUMPRODUCT(($B$4:AK$4>=AE$4-TeamStd_Duration+1)*($B$4:AK$4<=AE$4),$B$7:AK$7) | AF11: =SUMPRODUCT(($B$4:AK$4>=AF$4-TeamStd_Duration+1)*($B$4:AK$4<=AF$4),$B$7:AK$7) | AG11: =SUMPRODUCT(($B$4:AK$4>=AG$4-TeamStd_Duration+1)*($B$4:AK$4<=AG$4),$B$7:AK$7) | AH11: =SUMPRODUCT(($B$4:AK$4>=AH$4-TeamStd_Duration+1)*($B$4:AK$4<=AH$4),$B$7:AK$7) | AI11: =SUMPRODUCT(($B$4:AK$4>=AI$4-TeamStd_Duration+1)*($B$4:AK$4<=AI$4),$B$7:AK$7) | AJ11: =SUMPRODUCT(($B$4:AK$4>=AJ$4-TeamStd_Duration+1)*($B$4:AK$4<=AJ$4),$B$7:AK$7) | AK11: =SUMPRODUCT(($B$4:AK$4>=AK$4-TeamStd_Duration+1)*($B$4:AK$4<=AK$4),$B$7:AK$7)
A12: アクティブ：ライトニング（1ヶ月） | B12: =SUMPRODUCT(($B$4:AK$4>=B$4-Lightning_Duration+1)*($B$4:AK$4<=B$4),$B$8:AK$8) | C12: =SUMPRODUCT(($B$4:AK$4>=C$4-Lightning_Duration+1)*($B$4:AK$4<=C$4),$B$8:AK$8) | D12: =SUMPRODUCT(($B$4:AK$4>=D$4-Lightning_Duration+1)*($B$4:AK$4<=D$4),$B$8:AK$8) | E12: =SUMPRODUCT(($B$4:AK$4>=E$4-Lightning_Duration+1)*($B$4:AK$4<=E$4),$B$8:AK$8) | F12: =SUMPRODUCT(($B$4:AK$4>=F$4-Lightning_Duration+1)*($B$4:AK$4<=F$4),$B$8:AK$8) | G12: =SUMPRODUCT(($B$4:AK$4>=G$4-Lightning_Duration+1)*($B$4:AK$4<=G$4),$B$8:AK$8) | H12: =SUMPRODUCT(($B$4:AK$4>=H$4-Lightning_Duration+1)*($B$4:AK$4<=H$4),$B$8:AK$8) | I12: =SUMPRODUCT(($B$4:AK$4>=I$4-Lightning_Duration+1)*($B$4:AK$4<=I$4),$B$8:AK$8) | J12: =SUMPRODUCT(($B$4:AK$4>=J$4-Lightning_Duration+1)*($B$4:AK$4<=J$4),$B$8:AK$8) | K12: =SUMPRODUCT(($B$4:AK$4>=K$4-Lightning_Duration+1)*($B$4:AK$4<=K$4),$B$8:AK$8) | L12: =SUMPRODUCT(($B$4:AK$4>=L$4-Lightning_Duration+1)*($B$4:AK$4<=L$4),$B$8:AK$8) | M12: =SUMPRODUCT(($B$4:AK$4>=M$4-Lightning_Duration+1)*($B$4:AK$4<=M$4),$B$8:AK$8) | N12: =SUMPRODUCT(($B$4:AK$4>=N$4-Lightning_Duration+1)*($B$4:AK$4<=N$4),$B$8:AK$8) | O12: =SUMPRODUCT(($B$4:AK$4>=O$4-Lightning_Duration+1)*($B$4:AK$4<=O$4),$B$8:AK$8) | P12: =SUMPRODUCT(($B$4:AK$4>=P$4-Lightning_Duration+1)*($B$4:AK$4<=P$4),$B$8:AK$8) | Q12: =SUMPRODUCT(($B$4:AK$4>=Q$4-Lightning_Duration+1)*($B$4:AK$4<=Q$4),$B$8:AK$8) | R12: =SUMPRODUCT(($B$4:AK$4>=R$4-Lightning_Duration+1)*($B$4:AK$4<=R$4),$B$8:AK$8) | S12: =SUMPRODUCT(($B$4:AK$4>=S$4-Lightning_Duration+1)*($B$4:AK$4<=S$4),$B$8:AK$8) | T12: =SUMPRODUCT(($B$4:AK$4>=T$4-Lightning_Duration+1)*($B$4:AK$4<=T$4),$B$8:AK$8) | U12: =SUMPRODUCT(($B$4:AK$4>=U$4-Lightning_Duration+1)*($B$4:AK$4<=U$4),$B$8:AK$8) | V12: =SUMPRODUCT(($B$4:AK$4>=V$4-Lightning_Duration+1)*($B$4:AK$4<=V$4),$B$8:AK$8) | W12: =SUMPRODUCT(($B$4:AK$4>=W$4-Lightning_Duration+1)*($B$4:AK$4<=W$4),$B$8:AK$8) | X12: =SUMPRODUCT(($B$4:AK$4>=X$4-Lightning_Duration+1)*($B$4:AK$4<=X$4),$B$8:AK$8) | Y12: =SUMPRODUCT(($B$4:AK$4>=Y$4-Lightning_Duration+1)*($B$4:AK$4<=Y$4),$B$8:AK$8) | Z12: =SUMPRODUCT(($B$4:AK$4>=Z$4-Lightning_Duration+1)*($B$4:AK$4<=Z$4),$B$8:AK$8) | AA12: =SUMPRODUCT(($B$4:AK$4>=AA$4-Lightning_Duration+1)*($B$4:AK$4<=AA$4),$B$8:AK$8) | AB12: =SUMPRODUCT(($B$4:AK$4>=AB$4-Lightning_Duration+1)*($B$4:AK$4<=AB$4),$B$8:AK$8) | AC12: =SUMPRODUCT(($B$4:AK$4>=AC$4-Lightning_Duration+1)*($B$4:AK$4<=AC$4),$B$8:AK$8) | AD12: =SUMPRODUCT(($B$4:AK$4>=AD$4-Lightning_Duration+1)*($B$4:AK$4<=AD$4),$B$8:AK$8) | AE12: =SUMPRODUCT(($B$4:AK$4>=AE$4-Lightning_Duration+1)*($B$4:AK$4<=AE$4),$B$8:AK$8) | AF12: =SUMPRODUCT(($B$4:AK$4>=AF$4-Lightning_Duration+1)*($B$4:AK$4<=AF$4),$B$8:AK$8) | AG12: =SUMPRODUCT(($B$4:AK$4>=AG$4-Lightning_Duration+1)*($B$4:AK$4<=AG$4),$B$8:AK$8) | AH12: =SUMPRODUCT(($B$4:AK$4>=AH$4-Lightning_Duration+1)*($B$4:AK$4<=AH$4),$B$8:AK$8) | AI12: =SUMPRODUCT(($B$4:AK$4>=AI$4-Lightning_Duration+1)*($B$4:AK$4<=AI$4),$B$8:AK$8) | AJ12: =SUMPRODUCT(($B$4:AK$4>=AJ$4-Lightning_Duration+1)*($B$4:AK$4<=AJ$4),$B$8:AK$8) | AK12: =SUMPRODUCT(($B$4:AK$4>=AK$4-Lightning_Duration+1)*($B$4:AK$4<=AK$4),$B$8:AK$8)
A13: アクティブ：生成AI研修 | B13: =SUMPRODUCT(($B$4:AK$4>=B$4-Training_Duration+1)*($B$4:AK$4<=B$4),$B$9:AK$9) | C13: =SUMPRODUCT(($B$4:AK$4>=C$4-Training_Duration+1)*($B$4:AK$4<=C$4),$B$9:AK$9) | D13: =SUMPRODUCT(($B$4:AK$4>=D$4-Training_Duration+1)*($B$4:AK$4<=D$4),$B$9:AK$9) | E13: =SUMPRODUCT(($B$4:AK$4>=E$4-Training_Duration+1)*($B$4:AK$4<=E$4),$B$9:AK$9) | F13: =SUMPRODUCT(($B$4:AK$4>=F$4-Training_Duration+1)*($B$4:AK$4<=F$4),$B$9:AK$9) | G13: =SUMPRODUCT(($B$4:AK$4>=G$4-Training_Duration+1)*($B$4:AK$4<=G$4),$B$9:AK$9) | H13: =SUMPRODUCT(($B$4:AK$4>=H$4-Training_Duration+1)*($B$4:AK$4<=H$4),$B$9:AK$9) | I13: =SUMPRODUCT(($B$4:AK$4>=I$4-Training_Duration+1)*($B$4:AK$4<=I$4),$B$9:AK$9) | J13: =SUMPRODUCT(($B$4:AK$4>=J$4-Training_Duration+1)*($B$4:AK$4<=J$4),$B$9:AK$9) | K13: =SUMPRODUCT(($B$4:AK$4>=K$4-Training_Duration+1)*($B$4:AK$4<=K$4),$B$9:AK$9) | L13: =SUMPRODUCT(($B$4:AK$4>=L$4-Training_Duration+1)*($B$4:AK$4<=L$4),$B$9:AK$9) | M13: =SUMPRODUCT(($B$4:AK$4>=M$4-Training_Duration+1)*($B$4:AK$4<=M$4),$B$9:AK$9) | N13: =SUMPRODUCT(($B$4:AK$4>=N$4-Training_Duration+1)*($B$4:AK$4<=N$4),$B$9:AK$9) | O13: =SUMPRODUCT(($B$4:AK$4>=O$4-Training_Duration+1)*($B$4:AK$4<=O$4),$B$9:AK$9) | P13: =SUMPRODUCT(($B$4:AK$4>=P$4-Training_Duration+1)*($B$4:AK$4<=P$4),$B$9:AK$9) | Q13: =SUMPRODUCT(($B$4:AK$4>=Q$4-Training_Duration+1)*($B$4:AK$4<=Q$4),$B$9:AK$9) | R13: =SUMPRODUCT(($B$4:AK$4>=R$4-Training_Duration+1)*($B$4:AK$4<=R$4),$B$9:AK$9) | S13: =SUMPRODUCT(($B$4:AK$4>=S$4-Training_Duration+1)*($B$4:AK$4<=S$4),$B$9:AK$9) | T13: =SUMPRODUCT(($B$4:AK$4>=T$4-Training_Duration+1)*($B$4:AK$4<=T$4),$B$9:AK$9) | U13: =SUMPRODUCT(($B$4:AK$4>=U$4-Training_Duration+1)*($B$4:AK$4<=U$4),$B$9:AK$9) | V13: =SUMPRODUCT(($B$4:AK$4>=V$4-Training_Duration+1)*($B$4:AK$4<=V$4),$B$9:AK$9) | W13: =SUMPRODUCT(($B$4:AK$4>=W$4-Training_Duration+1)*($B$4:AK$4<=W$4),$B$9:AK$9) | X13: =SUMPRODUCT(($B$4:AK$4>=X$4-Training_Duration+1)*($B$4:AK$4<=X$4),$B$9:AK$9) | Y13: =SUMPRODUCT(($B$4:AK$4>=Y$4-Training_Duration+1)*($B$4:AK$4<=Y$4),$B$9:AK$9) | Z13: =SUMPRODUCT(($B$4:AK$4>=Z$4-Training_Duration+1)*($B$4:AK$4<=Z$4),$B$9:AK$9) | AA13: =SUMPRODUCT(($B$4:AK$4>=AA$4-Training_Duration+1)*($B$4:AK$4<=AA$4),$B$9:AK$9) | AB13: =SUMPRODUCT(($B$4:AK$4>=AB$4-Training_Duration+1)*($B$4:AK$4<=AB$4),$B$9:AK$9) | AC13: =SUMPRODUCT(($B$4:AK$4>=AC$4-Training_Duration+1)*($B$4:AK$4<=AC$4),$B$9:AK$9) | AD13: =SUMPRODUCT(($B$4:AK$4>=AD$4-Training_Duration+1)*($B$4:AK$4<=AD$4),$B$9:AK$9) | AE13: =SUMPRODUCT(($B$4:AK$4>=AE$4-Training_Duration+1)*($B$4:AK$4<=AE$4),$B$9:AK$9) | AF13: =SUMPRODUCT(($B$4:AK$4>=AF$4-Training_Duration+1)*($B$4:AK$4<=AF$4),$B$9:AK$9) | AG13: =SUMPRODUCT(($B$4:AK$4>=AG$4-Training_Duration+1)*($B$4:AK$4<=AG$4),$B$9:AK$9) | AH13: =SUMPRODUCT(($B$4:AK$4>=AH$4-Training_Duration+1)*($B$4:AK$4<=AH$4),$B$9:AK$9) | AI13: =SUMPRODUCT(($B$4:AK$4>=AI$4-Training_Duration+1)*($B$4:AK$4<=AI$4),$B$9:AK$9) | AJ13: =SUMPRODUCT(($B$4:AK$4>=AJ$4-Training_Duration+1)*($B$4:AK$4<=AJ$4),$B$9:AK$9) | AK13: =SUMPRODUCT(($B$4:AK$4>=AK$4-Training_Duration+1)*($B$4:AK$4<=AK$4),$B$9:AK$9)
A15: 計算：月次売上（収益認識）
A16: 売上：AIチーム開発（標準） | B16: =B$11*(TeamStd_Price/TeamStd_Duration) | C16: =C$11*(TeamStd_Price/TeamStd_Duration) | D16: =D$11*(TeamStd_Price/TeamStd_Duration) | E16: =E$11*(TeamStd_Price/TeamStd_Duration) | F16: =F$11*(TeamStd_Price/TeamStd_Duration) | G16: =G$11*(TeamStd_Price/TeamStd_Duration) | H16: =H$11*(TeamStd_Price/TeamStd_Duration) | I16: =I$11*(TeamStd_Price/TeamStd_Duration) | ... AK16: =AK$11*(TeamStd_Price/TeamStd_Duration)
A17: 売上：ライトニング（1ヶ月） | B17: =B$12*(Lightning_Price/Lightning_Duration) | C17: =C$12*(Lightning_Price/Lightning_Duration) | D17: =D$12*(Lightning_Price/Lightning_Duration) | E17: =E$12*(Lightning_Price/Lightning_Duration) | F17: =F$12*(Lightning_Price/Lightning_Duration) | G17: =G$12*(Lightning_Price/Lightning_Duration) | H17: =H$12*(Lightning_Price/Lightning_Duration) | I17: =I$12*(Lightning_Price/Lightning_Duration) | ... AK17: =AK$12*(Lightning_Price/Lightning_Duration)
A18: 売上：生成AI研修 | B18: =B$13*(Training_Price/Training_Duration) | C18: =C$13*(Training_Price/Training_Duration) | D18: =D$13*(Training_Price/Training_Duration) | E18: =E$13*(Training_Price/Training_Duration) | F18: =F$13*(Training_Price/Training_Duration) | G18: =G$13*(Training_Price/Training_Duration) | H18: =H$13*(Training_Price/Training_Duration) | I18: =I$13*(Training_Price/Training_Duration) | ... AK18: =AK$13*(Training_Price/Training_Duration)
A19: 売上合計 | B19: =SUM(B$16:B$18) | C19: =SUM(C$16:C$18) | D19: =SUM(D$16:D$18) | E19: =SUM(E$16:E$18) | F19: =SUM(F$16:F$18) | G19: =SUM(G$16:G$18) | H19: =SUM(H$16:H$18) | I19: =SUM(I$16:I$18) | ... AK19: =SUM(AK$16:AK$18)
A21: 計算：入金（簡易）— 前受＋残額分割（概算）
A22: 入金：AIチーム開発（標準） | B22: ==(TeamStd_Price*Upfront_Pct)*SUMPRODUCT(($B$4:AK$4=B$4),$B$7:AK$7)+=(TeamStd_Price*(1-Upfront_Pct)/Collect_Months)*SUMPRODUCT(($B$4:AK$4>=B$4-Collect_Months)*($B$4:AK$4<B$4),$B$7:AK$7) | C22: ==(TeamStd_Price*Upfront_Pct)*SUMPRODUCT(($B$4:AK$4=C$4),$B$7:AK$7)+=(TeamStd_Price*(1-Upfront_Pct)/Collect_Months)*SUMPRODUCT(($B$4:AK$4>=C$4-Collect_Months)*($B$4:AK$4<C$4),$B$7:AK$7) | D22: ==(TeamStd_Price*Upfront_Pct)*SUMPRODUCT(($B$4:AK$4=D$4),$B$7:AK$7)+=(TeamStd_Price*(1-Upfront_Pct)/Collect_Months)*SUMPRODUCT(($B$4:AK$4>=D$4-Collect_Months)*($B$4:AK$4<D$4),$B$7:AK$7) | E22: ==(TeamStd_Price*Upfront_Pct)*SUMPRODUCT(($B$4:AK$4=E$4),$B$7:AK$7)+=(TeamStd_Price*(1-Upfront_Pct)/Collect_Months)*SUMPRODUCT(($B$4:AK$4>=E$4-Collect_Months)*($B$4:AK$4<E$4),$B$7:AK$7) | F22: ==(TeamStd_Price*Upfront_Pct)*SUMPRODUCT(($B$4:AK$4=F$4),$B$7:AK$7)+=(TeamStd_Price*(1-Upfront_Pct)/Collect_Months)*SUMPRODUCT(($B$4:AK$4>=F$4-Collect_Months)*($B$4:AK$4<F$4),$B$7:AK$7) | G22: ==(TeamStd_Price*Upfront_Pct)*SUMPRODUCT(($B$4:AK$4=G$4),$B$7:AK$7)+=(TeamStd_Price*(1-Upfront_Pct)/Collect_Months)*SUMPRODUCT(($B$4:AK$4>=G$4-Collect_Months)*($B$4:AK$4<G$4),$B$7:AK$7) | H22: ==(TeamStd_Price*Upfront_Pct)*SUMPRODUCT(($B$4:AK$4=H$4),$B$7:AK$7)+=(TeamStd_Price*(1-Upfront_Pct)/Collect_Months)*SUMPRODUCT(($B$4:AK$4>=H$4-Collect_Months)*($B$4:AK$4<H$4),$B$7:AK$7) | I22: ==(TeamStd_Price*Upfront_Pct)*SUMPRODUCT(($B$4:AK$4=I$4),$B$7:AK$7)+=(TeamStd_Price*(1-Upfront_Pct)/Collect_Months)*SUMPRODUCT(($B$4:AK$4>=I$4-Collect_Months)*($B$4:AK$4<I$4),$B$7:AK$7) | J22: ==(TeamStd_Price*Upfront_Pct)*SUMPRODUCT(($B$4:AK$4=J$4),$B$7:AK$7)+=(TeamStd_Price*(1-Upfront_Pct)/Collect_Months)*SUMPRODUCT(($B$4:AK$4>=J$4-Collect_Months)*($B$4:AK$4<J$4),$B$7:AK$7) | K22: ==(TeamStd_Price*Upfront_Pct)*SUMPRODUCT(($B$4:AK$4=K$4),$B$7:AK$7)+=(TeamStd_Price*(1-Upfront_Pct)/Collect_Months)*SUMPRODUCT(($B$4:AK$4>=K$4-Collect_Months)*($B$4:AK$4<K$4),$B$7:AK$7) | L22: ==(TeamStd_Price*Upfront_Pct)*SUMPRODUCT(($B$4:AK$4=L$4),$B$7:AK$7)+=(TeamStd_Price*(1-Upfront_Pct)/Collect_Months)*SUMPRODUCT(($B$4:AK$4>=L$4-Collect_Months)*($B$4:AK$4<L$4),$B$7:AK$7) | M22: ==(TeamStd_Price*Upfront_Pct)*SUMPRODUCT(($B$4:AK$4=M$4),$B$7:AK$7)+=(TeamStd_Price*(1-Upfront_Pct)/Collect_Months)*SUMPRODUCT(($B$4:AK$4>=M$4-Collect_Months)*($B$4:AK$4<M$4),$B$7:AK$7) | N22: ==(TeamStd_Price*Upfront_Pct)*SUMPRODUCT(($B$4:AK$4=N$4),$B$7:AK$7)+=(TeamStd_Price*(1-Upfront_Pct)/Collect_Months)*SUMPRODUCT(($B$4:AK$4>=N$4-Collect_Months)*($B$4:AK$4<N$4),$B$7:AK$7) | O22: ==(TeamStd_Price*Upfront_Pct)*SUMPRODUCT(($B$4:AK$4=O$4),$B$7:AK$7)+=(TeamStd_Price*(1-Upfront_Pct)/Collect_Months)*SUMPRODUCT(($B$4:AK$4>=O$4-Collect_Months)*($B$4:AK$4<O$4),$B$7:AK$7) | P22: ==(TeamStd_Price*Upfront_Pct)*SUMPRODUCT(($B$4:AK$4=P$4),$B$7:AK$7)+=(TeamStd_Price*(1-Upfront_Pct)/Collect_Months)*SUMPRODUCT(($B$4:AK$4>=P$4-Collect_Months)*($B$4:AK$4<P$4),$B$7:AK$7) | Q22: ==(TeamStd_Price*Upfront_Pct)*SUMPRODUCT(($B$4:AK$4=Q$4),$B$7:AK$7)+=(TeamStd_Price*(1-Upfront_Pct)/Collect_Months)*SUMPRODUCT(($B$4:AK$4>=Q$4-Collect_Months)*($B$4:AK$4<Q$4),$B$7:AK$7) | R22: ==(TeamStd_Price*Upfront_Pct)*SUMPRODUCT(($B$4:AK$4=R$4),$B$7:AK$7)+=(TeamStd_Price*(1-Upfront_Pct)/Collect_Months)*SUMPRODUCT(($B$4:AK$4>=R$4-Collect_Months)*($B$4:AK$4<R$4),$B$7:AK$7) | S22: ==(TeamStd_Price*Upfront_Pct)*SUMPRODUCT(($B$4:AK$4=S$4),$B$7:AK$7)+=(TeamStd_Price*(1-Upfront_Pct)/Collect_Months)*SUMPRODUCT(($B$4:AK$4>=S$4-Collect_Months)*($B$4:AK$4<S$4),$B$7:AK$7) | T22: ==(TeamStd_Price*Upfront_Pct)*SUMPRODUCT(($B$4:AK$4=T$4),$B$7:AK$7)+=(TeamStd_Price*(1-Upfront_Pct)/Collect_Months)*SUMPRODUCT(($B$4:AK$4>=T$4-Collect_Months)*($B$4:AK$4<T$4),$B$7:AK$7) | U22: ==(TeamStd_Price*Upfront_Pct)*SUMPRODUCT(($B$4:AK$4=U$4),$B$7:AK$7)+=(TeamStd_Price*(1-Upfront_Pct)/Collect_Months)*SUMPRODUCT(($B$4:AK$4>=U$4-Collect_Months)*($B$4:AK$4<U$4),$B$7:AK$7) | V22: ==(TeamStd_Price*Upfront_Pct)*SUMPRODUCT(($B$4:AK$4=V$4),$B$7:AK$7)+=(TeamStd_Price*(1-Upfront_Pct)/Collect_Months)*SUMPRODUCT(($B$4:AK$4>=V$4-Collect_Months)*($B$4:AK$4<V$4),$B$7:AK$7) | W22: ==(TeamStd_Price*Upfront_Pct)*SUMPRODUCT(($B$4:AK$4=W$4),$B$7:AK$7)+=(TeamStd_Price*(1-Upfront_Pct)/Collect_Months)*SUMPRODUCT(($B$4:AK$4>=W$4-Collect_Months)*($B$4:AK$4<W$4),$B$7:AK$7) | X22: ==(TeamStd_Price*Upfront_Pct)*SUMPRODUCT(($B$4:AK$4=X$4),$B$7:AK$7)+=(TeamStd_Price*(1-Upfront_Pct)/Collect_Months)*SUMPRODUCT(($B$4:AK$4>=X$4-Collect_Months)*($B$4:AK$4<X$4),$B$7:AK$7) | Y22: ==(TeamStd_Price*Upfront_Pct)*SUMPRODUCT(($B$4:AK$4=Y$4),$B$7:AK$7)+=(TeamStd_Price*(1-Upfront_Pct)/Collect_Months)*SUMPRODUCT(($B$4:AK$4>=Y$4-Collect_Months)*($B$4:AK$4<Y$4),$B$7:AK$7) | Z22: ==(TeamStd_Price*Upfront_Pct)*SUMPRODUCT(($B$4:AK$4=Z$4),$B$7:AK$7)+=(TeamStd_Price*(1-Upfront_Pct)/Collect_Months)*SUMPRODUCT(($B$4:AK$4>=Z$4-Collect_Months)*($B$4:AK$4<Z$4),$B$7:AK$7) | AA22: ==(TeamStd_Price*Upfront_Pct)*SUMPRODUCT(($B$4:AK$4=AA$4),$B$7:AK$7)+=(TeamStd_Price*(1-Upfront_Pct)/Collect_Months)*SUMPRODUCT(($B$4:AK$4>=AA$4-Collect_Months)*($B$4:AK$4<AA$4),$B$7:AK$7) | AB22: ==(TeamStd_Price*Upfront_Pct)*SUMPRODUCT(($B$4:AK$4=AB$4),$B$7:AK$7)+=(TeamStd_Price*(1-Upfront_Pct)/Collect_Months)*SUMPRODUCT(($B$4:AK$4>=AB$4-Collect_Months)*($B$4:AK$4<AB$4),$B$7:AK$7) | AC22: ==(TeamStd_Price*Upfront_Pct)*SUMPRODUCT(($B$4:AK$4=AC$4),$B$7:AK$7)+=(TeamStd_Price*(1-Upfront_Pct)/Collect_Months)*SUMPRODUCT(($B$4:AK$4>=AC$4-Collect_Months)*($B$4:AK$4<AC$4),$B$7:AK$7) | AD22: ==(TeamStd_Price*Upfront_Pct)*SUMPRODUCT(($B$4:AK$4=AD$4),$B$7:AK$7)+=(TeamStd_Price*(1-Upfront_Pct)/Collect_Months)*SUMPRODUCT(($B$4:AK$4>=AD$4-Collect_Months)*($B$4:AK$4<AD$4),$B$7:AK$7) | AE22: ==(TeamStd_Price*Upfront_Pct)*SUMPRODUCT(($B$4:AK$4=AE$4),$B$7:AK$7)+=(TeamStd_Price*(1-Upfront_Pct)/Collect_Months)*SUMPRODUCT(($B$4:AK$4>=AE$4-Collect_Months)*($B$4:AK$4<AE$4),$B$7:AK$7) | AF22: ==(TeamStd_Price*Upfront_Pct)*SUMPRODUCT(($B$4:AK$4=AF$4),$B$7:AK$7)+=(TeamStd_Price*(1-Upfront_Pct)/Collect_Months)*SUMPRODUCT(($B$4:AK$4>=AF$4-Collect_Months)*($B$4:AK$4<AF$4),$B$7:AK$7) | AG22: ==(TeamStd_Price*Upfront_Pct)*SUMPRODUCT(($B$4:AK$4=AG$4),$B$7:AK$7)+=(TeamStd_Price*(1-Upfront_Pct)/Collect_Months)*SUMPRODUCT(($B$4:AK$4>=AG$4-Collect_Months)*($B$4:AK$4<AG$4),$B$7:AK$7) | AH22: ==(TeamStd_Price*Upfront_Pct)*SUMPRODUCT(($B$4:AK$4=AH$4),$B$7:AK$7)+=(TeamStd_Price*(1-Upfront_Pct)/Collect_Months)*SUMPRODUCT(($B$4:AK$4>=AH$4-Collect_Months)*($B$4:AK$4<AH$4),$B$7:AK$7) | AI22: ==(TeamStd_Price*Upfront_Pct)*SUMPRODUCT(($B$4:AK$4=AI$4),$B$7:AK$7)+=(TeamStd_Price*(1-Upfront_Pct)/Collect_Months)*SUMPRODUCT(($B$4:AK$4>=AI$4-Collect_Months)*($B$4:AK$4<AI$4),$B$7:AK$7) | AJ22: ==(TeamStd_Price*Upfront_Pct)*SUMPRODUCT(($B$4:AK$4=AJ$4),$B$7:AK$7)+=(TeamStd_Price*(1-Upfront_Pct)/Collect_Months)*SUMPRODUCT(($B$4:AK$4>=AJ$4-Collect_Months)*($B$4:AK$4<AJ$4),$B$7:AK$7) | AK22: ==(TeamStd_Price*Upfront_Pct)*SUMPRODUCT(($B$4:AK$4=AK$4),$B$7:AK$7)+=(TeamStd_Price*(1-Upfront_Pct)/Collect_Months)*SUMPRODUCT(($B$4:AK$4>=AK$4-Collect_Months)*($B$4:AK$4<AK$4),$B$7:AK$7)
A23: 入金：ライトニング（1ヶ月） | B23: ==(Lightning_Price*Upfront_Pct)*SUMPRODUCT(($B$4:AK$4=B$4),$B$8:AK$8)+=(Lightning_Price*(1-Upfront_Pct)/Collect_Months)*SUMPRODUCT(($B$4:AK$4>=B$4-Collect_Months)*($B$4:AK$4<B$4),$B$8:AK$8) | C23: ==(Lightning_Price*Upfront_Pct)*SUMPRODUCT(($B$4:AK$4=C$4),$B$8:AK$8)+=(Lightning_Price*(1-Upfront_Pct)/Collect_Months)*SUMPRODUCT(($B$4:AK$4>=C$4-Collect_Months)*($B$4:AK$4<C$4),$B$8:AK$8) | D23: ==(Lightning_Price*Upfront_Pct)*SUMPRODUCT(($B$4:AK$4=D$4),$B$8:AK$8)+=(Lightning_Price*(1-Upfront_Pct)/Collect_Months)*SUMPRODUCT(($B$4:AK$4>=D$4-Collect_Months)*($B$4:AK$4<D$4),$B$8:AK$8) | E23: ==(Lightning_Price*Upfront_Pct)*SUMPRODUCT(($B$4:AK$4=E$4),$B$8:AK$8)+=(Lightning_Price*(1-Upfront_Pct)/Collect_Months)*SUMPRODUCT(($B$4:AK$4>=E$4-Collect_Months)*($B$4:AK$4<E$4),$B$8:AK$8) | F23: ==(Lightning_Price*Upfront_Pct)*SUMPRODUCT(($B$4:AK$4=F$4),$B$8:AK$8)+=(Lightning_Price*(1-Upfront_Pct)/Collect_Months)*SUMPRODUCT(($B$4:AK$4>=F$4-Collect_Months)*($B$4:AK$4<F$4),$B$8:AK$8) | G23: ==(Lightning_Price*Upfront_Pct)*SUMPRODUCT(($B$4:AK$4=G$4),$B$8:AK$8)+=(Lightning_Price*(1-Upfront_Pct)/Collect_Months)*SUMPRODUCT(($B$4:AK$4>=G$4-Collect_Months)*($B$4:AK$4<G$4),$B$8:AK$8) | H23: ==(Lightning_Price*Upfront_Pct)*SUMPRODUCT(($B$4:AK$4=H$4),$B$8:AK$8)+=(Lightning_Price*(1-Upfront_Pct)/Collect_Months)*SUMPRODUCT(($B$4:AK$4>=H$4-Collect_Months)*($B$4:AK$4<H$4),$B$8:AK$8) | I23: ==(Lightning_Price*Upfront_Pct)*SUMPRODUCT(($B$4:AK$4=I$4),$B$8:AK$8)+=(Lightning_Price*(1-Upfront_Pct)/Collect_Months)*SUMPRODUCT(($B$4:AK$4>=I$4-Collect_Months)*($B$4:AK$4<I$4),$B$8:AK$8) | J23: ==(Lightning_Price*Upfront_Pct)*SUMPRODUCT(($B$4:AK$4=J$4),$B$8:AK$8)+=(Lightning_Price*(1-Upfront_Pct)/Collect_Months)*SUMPRODUCT(($B$4:AK$4>=J$4-Collect_Months)*($B$4:AK$4<J$4),$B$8:AK$8) | K23: ==(Lightning_Price*Upfront_Pct)*SUMPRODUCT(($B$4:AK$4=K$4),$B$8:AK$8)+=(Lightning_Price*(1-Upfront_Pct)/Collect_Months)*SUMPRODUCT(($B$4:AK$4>=K$4-Collect_Months)*($B$4:AK$4<K$4),$B$8:AK$8) | L23: ==(Lightning_Price*Upfront_Pct)*SUMPRODUCT(($B$4:AK$4=L$4),$B$8:AK$8)+=(Lightning_Price*(1-Upfront_Pct)/Collect_Months)*SUMPRODUCT(($B$4:AK$4>=L$4-Collect_Months)*($B$4:AK$4<L$4),$B$8:AK$8) | M23: ==(Lightning_Price*Upfront_Pct)*SUMPRODUCT(($B$4:AK$4=M$4),$B$8:AK$8)+=(Lightning_Price*(1-Upfront_Pct)/Collect_Months)*SUMPRODUCT(($B$4:AK$4>=M$4-Collect_Months)*($B$4:AK$4<M$4),$B$8:AK$8) | N23: ==(Lightning_Price*Upfront_Pct)*SUMPRODUCT(($B$4:AK$4=N$4),$B$8:AK$8)+=(Lightning_Price*(1-Upfront_Pct)/Collect_Months)*SUMPRODUCT(($B$4:AK$4>=N$4-Collect_Months)*($B$4:AK$4<N$4),$B$8:AK$8) | O23: ==(Lightning_Price*Upfront_Pct)*SUMPRODUCT(($B$4:AK$4=O$4),$B$8:AK$8)+=(Lightning_Price*(1-Upfront_Pct)/Collect_Months)*SUMPRODUCT(($B$4:AK$4>=O$4-Collect_Months)*($B$4:AK$4<O$4),$B$8:AK$8) | P23: ==(Lightning_Price*Upfront_Pct)*SUMPRODUCT(($B$4:AK$4=P$4),$B$8:AK$8)+=(Lightning_Price*(1-Upfront_Pct)/Collect_Months)*SUMPRODUCT(($B$4:AK$4>=P$4-Collect_Months)*($B$4:AK$4<P$4),$B$8:AK$8) | Q23: ==(Lightning_Price*Upfront_Pct)*SUMPRODUCT(($B$4:AK$4=Q$4),$B$8:AK$8)+=(Lightning_Price*(1-Upfront_Pct)/Collect_Months)*SUMPRODUCT(($B$4:AK$4>=Q$4-Collect_Months)*($B$4:AK$4<Q$4),$B$8:AK$8) | R23: ==(Lightning_Price*Upfront_Pct)*SUMPRODUCT(($B$4:AK$4=R$4),$B$8:AK$8)+=(Lightning_Price*(1-Upfront_Pct)/Collect_Months)*SUMPRODUCT(($B$4:AK$4>=R$4-Collect_Months)*($B$4:AK$4<R$4),$B$8:AK$8) | S23: ==(Lightning_Price*Upfront_Pct)*SUMPRODUCT(($B$4:AK$4=S$4),$B$8:AK$8)+=(Lightning_Price*(1-Upfront_Pct)/Collect_Months)*SUMPRODUCT(($B$4:AK$4>=S$4-Collect_Months)*($B$4:AK$4<S$4),$B$8:AK$8) | T23: ==(Lightning_Price*Upfront_Pct)*SUMPRODUCT(($B$4:AK$4=T$4),$B$8:AK$8)+=(Lightning_Price*(1-Upfront_Pct)/Collect_Months)*SUMPRODUCT(($B$4:AK$4>=T$4-Collect_Months)*($B$4:AK$4<T$4),$B$8:AK$8) | U23: ==(Lightning_Price*Upfront_Pct)*SUMPRODUCT(($B$4:AK$4=U$4),$B$8:AK$8)+=(Lightning_Price*(1-Upfront_Pct)/Collect_Months)*SUMPRODUCT(($B$4:AK$4>=U$4-Collect_Months)*($B$4:AK$4<U$4),$B$8:AK$8) | V23: ==(Lightning_Price*Upfront_Pct)*SUMPRODUCT(($B$4:AK$4=V$4),$B$8:AK$8)+=(Lightning_Price*(1-Upfront_Pct)/Collect_Months)*SUMPRODUCT(($B$4:AK$4>=V$4-Collect_Months)*($B$4:AK$4<V$4),$B$8:AK$8) | W23: ==(Lightning_Price*Upfront_Pct)*SUMPRODUCT(($B$4:AK$4=W$4),$B$8:AK$8)+=(Lightning_Price*(1-Upfront_Pct)/Collect_Months)*SUMPRODUCT(($B$4:AK$4>=W$4-Collect_Months)*($B$4:AK$4<W$4),$B$8:AK$8) | X23: ==(Lightning_Price*Upfront_Pct)*SUMPRODUCT(($B$4:AK$4=X$4),$B$8:AK$8)+=(Lightning_Price*(1-Upfront_Pct)/Collect_Months)*SUMPRODUCT(($B$4:AK$4>=X$4-Collect_Months)*($B$4:AK$4<X$4),$B$8:AK$8) | Y23: ==(Lightning_Price*Upfront_Pct)*SUMPRODUCT(($B$4:AK$4=Y$4),$B$8:AK$8)+=(Lightning_Price*(1-Upfront_Pct)/Collect_Months)*SUMPRODUCT(($B$4:AK$4>=Y$4-Collect_Months)*($B$4:AK$4<Y$4),$B$8:AK$8) | Z23: ==(Lightning_Price*Upfront_Pct)*SUMPRODUCT(($B$4:AK$4=Z$4),$B$8:AK$8)+=(Lightning_Price*(1-Upfront_Pct)/Collect_Months)*SUMPRODUCT(($B$4:AK$4>=Z$4-Collect_Months)*($B$4:AK$4<Z$4),$B$8:AK$8) | AA23: ==(Lightning_Price*Upfront_Pct)*SUMPRODUCT(($B$4:AK$4=AA$4),$B$8:AK$8)+=(Lightning_Price*(1-Upfront_Pct)/Collect_Months)*SUMPRODUCT(($B$4:AK$4>=AA$4-Collect_Months)*($B$4:AK$4<AA$4),$B$8:AK$8) | AB23: ==(Lightning_Price*Upfront_Pct)*SUMPRODUCT(($B$4:AK$4=AB$4),$B$8:AK$8)+=(Lightning_Price*(1-Upfront_Pct)/Collect_Months)*SUMPRODUCT(($B$4:AK$4>=AB$4-Collect_Months)*($B$4:AK$4<AB$4),$B$8:AK$8) | AC23: ==(Lightning_Price*Upfront_Pct)*SUMPRODUCT(($B$4:AK$4=AC$4),$B$8:AK$8)+=(Lightning_Price*(1-Upfront_Pct)/Collect_Months)*SUMPRODUCT(($B$4:AK$4>=AC$4-Collect_Months)*($B$4:AK$4<AC$4),$B$8:AK$8) | AD23: ==(Lightning_Price*Upfront_Pct)*SUMPRODUCT(($B$4:AK$4=AD$4),$B$8:AK$8)+=(Lightning_Price*(1-Upfront_Pct)/Collect_Months)*SUMPRODUCT(($B$4:AK$4>=AD$4-Collect_Months)*($B$4:AK$4<AD$4),$B$8:AK$8) | AE23: ==(Lightning_Price*Upfront_Pct)*SUMPRODUCT(($B$4:AK$4=AE$4),$B$8:AK$8)+=(Lightning_Price*(1-Upfront_Pct)/Collect_Months)*SUMPRODUCT(($B$4:AK$4>=AE$4-Collect_Months)*($B$4:AK$4<AE$4),$B$8:AK$8) | AF23: ==(Lightning_Price*Upfront_Pct)*SUMPRODUCT(($B$4:AK$4=AF$4),$B$8:AK$8)+=(Lightning_Price*(1-Upfront_Pct)/Collect_Months)*SUMPRODUCT(($B$4:AK$4>=AF$4-Collect_Months)*($B$4:AK$4<AF$4),$B$8:AK$8) | AG23: ==(Lightning_Price*Upfront_Pct)*SUMPRODUCT(($B$4:AK$4=AG$4),$B$8:AK$8)+=(Lightning_Price*(1-Upfront_Pct)/Collect_Months)*SUMPRODUCT(($B$4:AK$4>=AG$4-Collect_Months)*($B$4:AK$4<AG$4),$B$8:AK$8) | AH23: ==(Lightning_Price*Upfront_Pct)*SUMPRODUCT(($B$4:AK$4=AH$4),$B$8:AK$8)+=(Lightning_Price*(1-Upfront_Pct)/Collect_Months)*SUMPRODUCT(($B$4:AK$4>=AH$4-Collect_Months)*($B$4:AK$4<AH$4),$B$8:AK$8) | AI23: ==(Lightning_Price*Upfront_Pct)*SUMPRODUCT(($B$4:AK$4=AI$4),$B$8:AK$8)+=(Lightning_Price*(1-Upfront_Pct)/Collect_Months)*SUMPRODUCT(($B$4:AK$4>=AI$4-Collect_Months)*($B$4:AK$4<AI$4),$B$8:AK$8) | AJ23: ==(Lightning_Price*Upfront_Pct)*SUMPRODUCT(($B$4:AK$4=AJ$4),$B$8:AK$8)+=(Lightning_Price*(1-Upfront_Pct)/Collect_Months)*SUMPRODUCT(($B$4:AK$4>=AJ$4-Collect_Months)*($B$4:AK$4<AJ$4),$B$8:AK$8) | AK23: ==(Lightning_Price*Upfront_Pct)*SUMPRODUCT(($B$4:AK$4=AK$4),$B$8:AK$8)+=(Lightning_Price*(1-Upfront_Pct)/Collect_Months)*SUMPRODUCT(($B$4:AK$4>=AK$4-Collect_Months)*($B$4:AK$4<AK$4),$B$8:AK$8)
A24: 入金：生成AI研修 | B24: ==(Training_Price*Upfront_Pct)*SUMPRODUCT(($B$4:AK$4=B$4),$B$9:AK$9)+=(Training_Price*(1-Upfront_Pct)/Collect_Months)*SUMPRODUCT(($B$4:AK$4>=B$4-Collect_Months)*($B$4:AK$4<B$4),$B$9:AK$9) | C24: ==(Training_Price*Upfront_Pct)*SUMPRODUCT(($B$4:AK$4=C$4),$B$9:AK$9)+=(Training_Price*(1-Upfront_Pct)/Collect_Months)*SUMPRODUCT(($B$4:AK$4>=C$4-Collect_Months)*($B$4:AK$4<C$4),$B$9:AK$9) | D24: ==(Training_Price*Upfront_Pct)*SUMPRODUCT(($B$4:AK$4=D$4),$B$9:AK$9)+=(Training_Price*(1-Upfront_Pct)/Collect_Months)*SUMPRODUCT(($B$4:AK$4>=D$4-Collect_Months)*($B$4:AK$4<D$4),$B$9:AK$9) | E24: ==(Training_Price*Upfront_Pct)*SUMPRODUCT(($B$4:AK$4=E$4),$B$9:AK$9)+=(Training_Price*(1-Upfront_Pct)/Collect_Months)*SUMPRODUCT(($B$4:AK$4>=E$4-Collect_Months)*($B$4:AK$4<E$4),$B$9:AK$9) | F24: ==(Training_Price*Upfront_Pct)*SUMPRODUCT(($B$4:AK$4=F$4),$B$9:AK$9)+=(Training_Price*(1-Upfront_Pct)/Collect_Months)*SUMPRODUCT(($B$4:AK$4>=F$4-Collect_Months)*($B$4:AK$4<F$4),$B$9:AK$9) | G24: ==(Training_Price*Upfront_Pct)*SUMPRODUCT(($B$4:AK$4=G$4),$B$9:AK$9)+=(Training_Price*(1-Upfront_Pct)/Collect_Months)*SUMPRODUCT(($B$4:AK$4>=G$4-Collect_Months)*($B$4:AK$4<G$4),$B$9:AK$9) | H24: ==(Training_Price*Upfront_Pct)*SUMPRODUCT(($B$4:AK$4=H$4),$B$9:AK$9)+=(Training_Price*(1-Upfront_Pct)/Collect_Months)*SUMPRODUCT(($B$4:AK$4>=H$4-Collect_Months)*($B$4:AK$4<H$4),$B$9:AK$9) | I24: ==(Training_Price*Upfront_Pct)*SUMPRODUCT(($B$4:AK$4=I$4),$B$9:AK$9)+=(Training_Price*(1-Upfront_Pct)/Collect_Months)*SUMPRODUCT(($B$4:AK$4>=I$4-Collect_Months)*($B$4:AK$4<I$4),$B$9:AK$9) | J24: ==(Training_Price*Upfront_Pct)*SUMPRODUCT(($B$4:AK$4=J$4),$B$9:AK$9)+=(Training_Price*(1-Upfront_Pct)/Collect_Months)*SUMPRODUCT(($B$4:AK$4>=J$4-Collect_Months)*($B$4:AK$4<J$4),$B$9:AK$9) | K24: ==(Training_Price*Upfront_Pct)*SUMPRODUCT(($B$4:AK$4=K$4),$B$9:AK$9)+=(Training_Price*(1-Upfront_Pct)/Collect_Months)*SUMPRODUCT(($B$4:AK$4>=K$4-Collect_Months)*($B$4:AK$4<K$4),$B$9:AK$9) | L24: ==(Training_Price*Upfront_Pct)*SUMPRODUCT(($B$4:AK$4=L$4),$B$9:AK$9)+=(Training_Price*(1-Upfront_Pct)/Collect_Months)*SUMPRODUCT(($B$4:AK$4>=L$4-Collect_Months)*($B$4:AK$4<L$4),$B$9:AK$9) | M24: ==(Training_Price*Upfront_Pct)*SUMPRODUCT(($B$4:AK$4=M$4),$B$9:AK$9)+=(Training_Price*(1-Upfront_Pct)/Collect_Months)*SUMPRODUCT(($B$4:AK$4>=M$4-Collect_Months)*($B$4:AK$4<M$4),$B$9:AK$9) | N24: ==(Training_Price*Upfront_Pct)*SUMPRODUCT(($B$4:AK$4=N$4),$B$9:AK$9)+=(Training_Price*(1-Upfront_Pct)/Collect_Months)*SUMPRODUCT(($B$4:AK$4>=N$4-Collect_Months)*($B$4:AK$4<N$4),$B$9:AK$9) | O24: ==(Training_Price*Upfront_Pct)*SUMPRODUCT(($B$4:AK$4=O$4),$B$9:AK$9)+=(Training_Price*(1-Upfront_Pct)/Collect_Months)*SUMPRODUCT(($B$4:AK$4>=O$4-Collect_Months)*($B$4:AK$4<O$4),$B$9:AK$9) | P24: ==(Training_Price*Upfront_Pct)*SUMPRODUCT(($B$4:AK$4=P$4),$B$9:AK$9)+=(Training_Price*(1-Upfront_Pct)/Collect_Months)*SUMPRODUCT(($B$4:AK$4>=P$4-Collect_Months)*($B$4:AK$4<P$4),$B$9:AK$9) | Q24: ==(Training_Price*Upfront_Pct)*SUMPRODUCT(($B$4:AK$4=Q$4),$B$9:AK$9)+=(Training_Price*(1-Upfront_Pct)/Collect_Months)*SUMPRODUCT(($B$4:AK$4>=Q$4-Collect_Months)*($B$4:AK$4<Q$4),$B$9:AK$9) | R24: ==(Training_Price*Upfront_Pct)*SUMPRODUCT(($B$4:AK$4=R$4),$B$9:AK$9)+=(Training_Price*(1-Upfront_Pct)/Collect_Months)*SUMPRODUCT(($B$4:AK$4>=R$4-Collect_Months)*($B$4:AK$4<R$4),$B$9:AK$9) | S24: ==(Training_Price*Upfront_Pct)*SUMPRODUCT(($B$4:AK$4=S$4),$B$9:AK$9)+=(Training_Price*(1-Upfront_Pct)/Collect_Months)*SUMPRODUCT(($B$4:AK$4>=S$4-Collect_Months)*($B$4:AK$4<S$4),$B$9:AK$9) | T24: ==(Training_Price*Upfront_Pct)*SUMPRODUCT(($B$4:AK$4=T$4),$B$9:AK$9)+=(Training_Price*(1-Upfront_Pct)/Collect_Months)*SUMPRODUCT(($B$4:AK$4>=T$4-Collect_Months)*($B$4:AK$4<T$4),$B$9:AK$9) | U24: ==(Training_Price*Upfront_Pct)*SUMPRODUCT(($B$4:AK$4=U$4),$B$9:AK$9)+=(Training_Price*(1-Upfront_Pct)/Collect_Months)*SUMPRODUCT(($B$4:AK$4>=U$4-Collect_Months)*($B$4:AK$4<U$4),$B$9:AK$9) | V24: ==(Training_Price*Upfront_Pct)*SUMPRODUCT(($B$4:AK$4=V$4),$B$9:AK$9)+=(Training_Price*(1-Upfront_Pct)/Collect_Months)*SUMPRODUCT(($B$4:AK$4>=V$4-Collect_Months)*($B$4:AK$4<V$4),$B$9:AK$9) | W24: ==(Training_Price*Upfront_Pct)*SUMPRODUCT(($B$4:AK$4=W$4),$B$9:AK$9)+=(Training_Price*(1-Upfront_Pct)/Collect_Months)*SUMPRODUCT(($B$4:AK$4>=W$4-Collect_Months)*($B$4:AK$4<W$4),$B$9:AK$9) | X24: ==(Training_Price*Upfront_Pct)*SUMPRODUCT(($B$4:AK$4=X$4),$B$9:AK$9)+=(Training_Price*(1-Upfront_Pct)/Collect_Months)*SUMPRODUCT(($B$4:AK$4>=X$4-Collect_Months)*($B$4:AK$4<X$4),$B$9:AK$9) | Y24: ==(Training_Price*Upfront_Pct)*SUMPRODUCT(($B$4:AK$4=Y$4),$B$9:AK$9)+=(Training_Price*(1-Upfront_Pct)/Collect_Months)*SUMPRODUCT(($B$4:AK$4>=Y$4-Collect_Months)*($B$4:AK$4<Y$4),$B$9:AK$9) | Z24: ==(Training_Price*Upfront_Pct)*SUMPRODUCT(($B$4:AK$4=Z$4),$B$9:AK$9)+=(Training_Price*(1-Upfront_Pct)/Collect_Months)*SUMPRODUCT(($B$4:AK$4>=Z$4-Collect_Months)*($B$4:AK$4<Z$4),$B$9:AK$9) | AA24: ==(Training_Price*Upfront_Pct)*SUMPRODUCT(($B$4:AK$4=AA$4),$B$9:AK$9)+=(Training_Price*(1-Upfront_Pct)/Collect_Months)*SUMPRODUCT(($B$4:AK$4>=AA$4-Collect_Months)*($B$4:AK$4<AA$4),$B$9:AK$9) | AB24: ==(Training_Price*Upfront_Pct)*SUMPRODUCT(($B$4:AK$4=AB$4),$B$9:AK$9)+=(Training_Price*(1-Upfront_Pct)/Collect_Months)*SUMPRODUCT(($B$4:AK$4>=AB$4-Collect_Months)*($B$4:AK$4<AB$4),$B$9:AK$9) | AC24: ==(Training_Price*Upfront_Pct)*SUMPRODUCT(($B$4:AK$4=AC$4),$B$9:AK$9)+=(Training_Price*(1-Upfront_Pct)/Collect_Months)*SUMPRODUCT(($B$4:AK$4>=AC$4-Collect_Months)*($B$4:AK$4<AC$4),$B$9:AK$9) | AD24: ==(Training_Price*Upfront_Pct)*SUMPRODUCT(($B$4:AK$4=AD$4),$B$9:AK$9)+=(Training_Price*(1-Upfront_Pct)/Collect_Months)*SUMPRODUCT(($B$4:AK$4>=AD$4-Collect_Months)*($B$4:AK$4<AD$4),$B$9:AK$9) | AE24: ==(Training_Price*Upfront_Pct)*SUMPRODUCT(($B$4:AK$4=AE$4),$B$9:AK$9)+=(Training_Price*(1-Upfront_Pct)/Collect_Months)*SUMPRODUCT(($B$4:AK$4>=AE$4-Collect_Months)*($B$4:AK$4<AE$4),$B$9:AK$9) | AF24: ==(Training_Price*Upfront_Pct)*SUMPRODUCT(($B$4:AK$4=AF$4),$B$9:AK$9)+=(Training_Price*(1-Upfront_Pct)/Collect_Months)*SUMPRODUCT(($B$4:AK$4>=AF$4-Collect_Months)*($B$4:AK$4<AF$4),$B$9:AK$9) | AG24: ==(Training_Price*Upfront_Pct)*SUMPRODUCT(($B$4:AK$4=AG$4),$B$9:AK$9)+=(Training_Price*(1-Upfront_Pct)/Collect_Months)*SUMPRODUCT(($B$4:AK$4>=AG$4-Collect_Months)*($B$4:AK$4<AG$4),$B$9:AK$9) | AH24: ==(Training_Price*Upfront_Pct)*SUMPRODUCT(($B$4:AK$4=AH$4),$B$9:AK$9)+=(Training_Price*(1-Upfront_Pct)/Collect_Months)*SUMPRODUCT(($B$4:AK$4>=AH$4-Collect_Months)*($B$4:AK$4<AH$4),$B$9:AK$9) | AI24: ==(Training_Price*Upfront_Pct)*SUMPRODUCT(($B$4:AK$4=AI$4),$B$9:AK$9)+=(Training_Price*(1-Upfront_Pct)/Collect_Months)*SUMPRODUCT(($B$4:AK$4>=AI$4-Collect_Months)*($B$4:AK$4<AI$4),$B$9:AK$9) | AJ24: ==(Training_Price*Upfront_Pct)*SUMPRODUCT(($B$4:AK$4=AJ$4),$B$9:AK$9)+=(Training_Price*(1-Upfront_Pct)/Collect_Months)*SUMPRODUCT(($B$4:AK$4>=AJ$4-Collect_Months)*($B$4:AK$4<AJ$4),$B$9:AK$9) | AK24: ==(Training_Price*Upfront_Pct)*SUMPRODUCT(($B$4:AK$4=AK$4),$B$9:AK$9)+=(Training_Price*(1-Upfront_Pct)/Collect_Months)*SUMPRODUCT(($B$4:AK$4>=AK$4-Collect_Months)*($B$4:AK$4<AK$4),$B$9:AK$9)
A25: 入金合計 | B25: =SUM(B$22:B$24) | C25: =SUM(C$22:C$24) | D25: =SUM(D$22:D$24) | E25: =SUM(E$22:E$24) | F25: =SUM(F$22:F$24) | G25: =SUM(G$22:G$24) | H25: =SUM(H$22:H$24) | I25: =SUM(I$22:I$24) | ... AK25: =SUM(AK$22:AK$24)

Sheet 5_原価・販管費
A1: 原価・販管費（月次）
A3: 項目 | B3: 2026-01 | C3: 2026-02 | D3: 2026-03 | E3: 2026-04 | F3: 2026-05 | G3: 2026-06 | H3: 2026-07 | I3: 2026-08 | J3: 2026-09 | K3: 2026-10 | L3: 2026-11 | M3: 2026-12 | N3: 2027-01 | O3: 2027-02 | P3: 2027-03 | Q3: 2027-04 | R3: 2027-05 | S3: 2027-06 | T3: 2027-07 | U3: 2027-08 | V3: 2027-09 | W3: 2027-10 | X3: 2027-11 | Y3: 2027-12 | Z3: 2028-01 | AA3: 2028-02 | AB3: 2028-03 | AC3: 2028-04 | AD3: 2028-05 | AE3: 2028-06 | AF3: 2028-07 | AG3: 2028-08 | AH3: 2028-09 | AI3: 2028-10 | AJ3: 2028-11 | AK3: 2028-12
A5: 原価（変動）
A6: 原価：AIチーム開発（標準） | B6: ='4_売上計画'!B$11*'2_プラン設計'!$B$15 | C6: ='4_売上計画'!C$11*'2_プラン設計'!$B$15 | D6: ='4_売上計画'!D$11*'2_プラン設計'!$B$15 | E6: ='4_売上計画'!E$11*'2_プラン設計'!$B$15 | F6: ='4_売上計画'!F$11*'2_プラン設計'!$B$15 | G6: ='4_売上計画'!G$11*'2_プラン設計'!$B$15 | H6: ='4_売上計画'!H$11*'2_プラン設計'!$B$15 | I6: ='4_売上計画'!I$11*'2_プラン設計'!$B$15 | ... AK6: ='4_売上計画'!AK$11*'2_プラン設計'!$B$15
A7: 原価：ライトニング（1ヶ月） | B7: ='4_売上計画'!B$12*'2_プラン設計'!$C$15 | C7: ='4_売上計画'!C$12*'2_プラン設計'!$C$15 | D7: ='4_売上計画'!D$12*'2_プラン設計'!$C$15 | E7: ='4_売上計画'!E$12*'2_プラン設計'!$C$15 | F7: ='4_売上計画'!F$12*'2_プラン設計'!$C$15 | G7: ='4_売上計画'!G$12*'2_プラン設計'!$C$15 | H7: ='4_売上計画'!H$12*'2_プラン設計'!$C$15 | I7: ='4_売上計画'!I$12*'2_プラン設計'!$C$15 | ... AK7: ='4_売上計画'!AK$12*'2_プラン設計'!$C$15
A8: 原価：生成AI研修 | B8: ='4_売上計画'!B$13*'2_プラン設計'!$D$15 | C8: ='4_売上計画'!C$13*'2_プラン設計'!$D$15 | D8: ='4_売上計画'!D$13*'2_プラン設計'!$D$15 | E8: ='4_売上計画'!E$13*'2_プラン設計'!$D$15 | F8: ='4_売上計画'!F$13*'2_プラン設計'!$D$15 | G8: ='4_売上計画'!G$13*'2_プラン設計'!$D$15 | H8: ='4_売上計画'!H$13*'2_プラン設計'!$D$15 | I8: ='4_売上計画'!I$13*'2_プラン設計'!$D$15 | ... AK8: ='4_売上計画'!AK$13*'2_プラン設計'!$D$15
A9: 原価合計 | B9: =SUM(B$6:B$8) | C9: =SUM(C$6:C$8) | D9: =SUM(D$6:D$8) | E9: =SUM(E$6:E$8) | F9: =SUM(F$6:F$8) | G9: =SUM(G$6:G$8) | H9: =SUM(H$6:H$8) | I9: =SUM(I$6:I$8) | ... AK9: =SUM(AK$6:AK$8)
A11: 販管費（固定）
A12: マーケ費 | B12: =Mkt_Fixed | C12: =Mkt_Fixed | D12: =Mkt_Fixed | E12: =Mkt_Fixed | F12: =Mkt_Fixed | G12: =Mkt_Fixed | H12: =Mkt_Fixed | I12: =Mkt_Fixed | ... AK12: =Mkt_Fixed
A13: ツール費 | B13: =Tools_Fixed | C13: =Tools_Fixed | D13: =Tools_Fixed | E13: =Tools_Fixed | F13: =Tools_Fixed | G13: =Tools_Fixed | H13: =Tools_Fixed | I13: =Tools_Fixed | ... AK13: =Tools_Fixed
A14: バックオフィス | B14: =BackOffice_Fixed | C14: =BackOffice_Fixed | D14: =BackOffice_Fixed | E14: =BackOffice_Fixed | F14: =BackOffice_Fixed | G14: =BackOffice_Fixed | H14: =BackOffice_Fixed | I14: =BackOffice_Fixed | ... AK14: =BackOffice_Fixed
A15: その他固定費 | B15: =Other_Fixed | C15: =Other_Fixed | D15: =Other_Fixed | E15: =Other_Fixed | F15: =Other_Fixed | G15: =Other_Fixed | H15: =Other_Fixed | I15: =Other_Fixed | ... AK15: =Other_Fixed
A16: 販管費 合計 | B16: =SUM(B$12:B$15) | C16: =SUM(C$12:C$15) | D16: =SUM(D$12:D$15) | E16: =SUM(E$12:E$15) | F16: =SUM(F$12:F$15) | G16: =SUM(G$12:G$15) | H16: =SUM(H$12:H$15) | I16: =SUM(I$12:I$15) | ... AK16: =SUM(AK$12:AK$15)
A18: 合計（原価＋販管費）
A19: 支出合計（P/L用） | B19: =B$9+B$16 | C19: =C$9+C$16 | D19: =D$9+D$16 | E19: =E$9+E$16 | F19: =F$9+F$16 | G19: =G$9+G$16 | H19: =H$9+H$16 | I19: =I$9+I$16 | ... AK19: =AK$9+AK$16

Sheet 6_P&L
A1: 損益計算書（P&L）月次
A3: 項目 | B3: 2026-01 | C3: 2026-02 | D3: 2026-03 | E3: 2026-04 | F3: 2026-05 | G3: 2026-06 | H3: 2026-07 | I3: 2026-08 | J3: 2026-09 | K3: 2026-10 | L3: 2026-11 | M3: 2026-12 | N3: 2027-01 | O3: 2027-02 | P3: 2027-03 | Q3: 2027-04 | R3: 2027-05 | S3: 2027-06 | T3: 2027-07 | U3: 2027-08 | V3: 2027-09 | W3: 2027-10 | X3: 2027-11 | Y3: 2027-12 | Z3: 2028-01 | AA3: 2028-02 | AB3: 2028-03 | AC3: 2028-04 | AD3: 2028-05 | AE3: 2028-06 | AF3: 2028-07 | AG3: 2028-08 | AH3: 2028-09 | AI3: 2028-10 | AJ3: 2028-11 | AK3: 2028-12
A5: 売上高 | B5: ='4_売上計画'!B$19 | C5: ='4_売上計画'!C$19 | D5: ='4_売上計画'!D$19 | E5: ='4_売上計画'!E$19 | F5: ='4_売上計画'!F$19 | G5: ='4_売上計画'!G$19 | H5: ='4_売上計画'!H$19 | I5: ='4_売上計画'!I$19 | ... AK5: ='4_売上計画'!AK$19
A6: 原価 | B6: ='5_原価・販管費'!B$9 | C6: ='5_原価・販管費'!C$9 | D6: ='5_原価・販管費'!D$9 | E6: ='5_原価・販管費'!E$9 | F6: ='5_原価・販管費'!F$9 | G6: ='5_原価・販管費'!G$9 | H6: ='5_原価・販管費'!H$9 | I6: ='5_原価・販管費'!I$9 | ... AK6: ='5_原価・販管費'!AK$9
A7: 粗利 | B7: =B$5-B$6 | C7: =C$5-C$6 | D7: =D$5-D$6 | E7: =E$5-E$6 | F7: =F$5-F$6 | G7: =G$5-G$6 | H7: =H$5-H$6 | I7: =I$5-I$6 | ... AK7: =AK$5-AK$6
A8: 粗利率 | B8: =IF(B$5=0,0,B$7/B$5) | C8: =IF(C$5=0,0,C$7/C$5) | D8: =IF(D$5=0,0,D$7/D$5) | E8: =IF(E$5=0,0,E$7/E$5) | F8: =IF(F$5=0,0,F$7/F$5) | G8: =IF(G$5=0,0,G$7/G$5) | H8: =IF(H$5=0,0,H$7/H$5) | I8: =IF(I$5=0,0,I$7/I$5) | ... AK8: =IF(AK$5=0,0,AK$7/AK$5)
A9: 販管費 | B9: ='5_原価・販管費'!B$16 | C9: ='5_原価・販管費'!C$16 | D9: ='5_原価・販管費'!D$16 | E9: ='5_原価・販管費'!E$16 | F9: ='5_原価・販管費'!F$16 | G9: ='5_原価・販管費'!G$16 | H9: ='5_原価・販管費'!H$16 | I9: ='5_原価・販管費'!I$16 | ... AK9: ='5_原価・販管費'!AK$16
A10: EBITDA（概算） | B10: =B$7-B$9 | C10: =C$7-C$9 | D10: =D$7-D$9 | E10: =E$7-E$9 | F10: =F$7-F$9 | G10: =G$7-G$9 | H10: =H$7-H$9 | I10: =I$7-I$9 | ... AK10: =AK$7-AK$9
A11: EBITDA率 | B11: =IF(B$5=0,0,B$10/B$5) | C11: =IF(C$5=0,0,C$10/C$5) | D11: =IF(D$5=0,0,D$10/D$5) | E11: =IF(E$5=0,0,E$10/E$5) | F11: =IF(F$5=0,0,F$10/F$5) | G11: =IF(G$5=0,0,G$10/G$5) | H11: =IF(H$5=0,0,H$10/H$5) | I11: =IF(I$5=0,0,I$10/I$5) | ... AK11: =IF(AK$5=0,0,AK$10/AK$5)
A13: 累計（参考）
A14: 累計売上 | B14: =SUM($B$5:B$5) | C14: =SUM($B$5:C$5) | D14: =SUM($B$5:D$5) | E14: =SUM($B$5:E$5) | F14: =SUM($B$5:F$5) | G14: =SUM($B$5:G$5) | H14: =SUM($B$5:H$5) | I14: =SUM($B$5:I$5) | ... AK14: =SUM($B$5:AK$5)
A15: 累計EBITDA | B15: =SUM($B$10:B$10) | C15: =SUM($B$10:C$10) | D15: =SUM($B$10:D$10) | E15: =SUM($B$10:E$10) | F15: =SUM($B$10:F$10) | G15: =SUM($B$10:G$10) | H15: =SUM($B$10:H$10) | I15: =SUM($B$10:I$10) | ... AK15: =SUM($B$10:AK$10)

Sheet 7_Cash
A1: キャッシュフロー（簡易）
A3: 初期現金残高（入力） | B3: 2000000 | C3: 例：2,000,000円。必要に応じて変更。
A5: 項目 | B5: 2026-01 | C5: 2026-02 | D5: 2026-03 | E5: 2026-04 | F5: 2026-05 | G5: 2026-06 | H5: 2026-07 | I5: 2026-08 | J5: 2026-09 | K5: 2026-10 | L5: 2026-11 | M5: 2026-12 | N5: 2027-01 | O5: 2027-02 | P5: 2027-03 | Q5: 2027-04 | R5: 2027-05 | S5: 2027-06 | T5: 2027-07 | U5: 2027-08 | V5: 2027-09 | W5: 2027-10 | X5: 2027-11 | Y5: 2027-12 | Z5: 2028-01 | AA5: 2028-02 | AB5: 2028-03 | AC5: 2028-04 | AD5: 2028-05 | AE5: 2028-06 | AF5: 2028-07 | AG5: 2028-08 | AH5: 2028-09 | AI5: 2028-10 | AJ5: 2028-11 | AK5: 2028-12
A7: 入金合計 | B7: ='4_売上計画'!B$25 | C7: ='4_売上計画'!C$25 | D7: ='4_売上計画'!D$25 | E7: ='4_売上計画'!E$25 | F7: ='4_売上計画'!F$25 | G7: ='4_売上計画'!G$25 | H7: ='4_売上計画'!H$25 | I7: ='4_売上計画'!I$25 | ... AK7: ='4_売上計画'!AK$25
A8: 支出合計 | B8: ='5_原価・販管費'!B$19 | C8: ='5_原価・販管費'!C$19 | D8: ='5_原価・販管費'!D$19 | E8: ='5_原価・販管費'!E$19 | F8: ='5_原価・販管費'!F$19 | G8: ='5_原価・販管費'!G$19 | H8: ='5_原価・販管費'!H$19 | I8: ='5_原価・販管費'!I$19 | ... AK8: ='5_原価・販管費'!AK$19
A9: ネットCF | B9: =B$7-B$8 | C9: =C$7-C$8 | D9: =D$7-D$8 | E9: =E$7-E$8 | F9: =F$7-F$8 | G9: =G$7-G$8 | H9: =H$7-H$8 | I9: =I$7-I$8 | ... AK9: =AK$7-AK$8
A10: 現金残高 | B10: =$B$3+B$9 | C10: =B$10+C$9 | D10: =C$10+D$9 | E10: =D$10+E$9 | F10: =E$10+F$9 | G10: =F$10+G$9 | H10: =G$10+H$9 | I10: =H$10+I$9 | J10: =I$10+J$9 | ... AK10: =AJ$10+AK$9
A11: 警告（残高<0） | B11: =IF(B$10<0,B$10,0) | C11: =IF(C$10<0,C$10,0) | D11: =IF(D$10<0,D$10,0) | E11: =IF(E$10<0,E$10,0) | F11: =IF(F$10<0,F$10,0) | G11: =IF(G$10<0,G$10,0) | H11: =IF(H$10<0,H$10,0) | I11: =IF(I$10<0,I$10,0) | ... AK11: =IF(AK$10<0,AK$10,0)

Sheet 3_容量モデル
A1: 容量モデル（月次）— 需要が供給（稼働上限）を超えると赤字化・品質低下リスク
A3: 項目 | B3: 2026-01 | C3: 2026-02 | D3: 2026-03 | E3: 2026-04 | F3: 2026-05 | G3: 2026-06 | H3: 2026-07 | I3: 2026-08 | J3: 2026-09 | K3: 2026-10 | L3: 2026-11 | M3: 2026-12 | N3: 2027-01 | O3: 2027-02 | P3: 2027-03 | Q3: 2027-04 | R3: 2027-05 | S3: 2027-06 | T3: 2027-07 | U3: 2027-08 | V3: 2027-09 | W3: 2027-10 | X3: 2027-11 | Y3: 2027-12 | Z3: 2028-01 | AA3: 2028-02 | AB3: 2028-03 | AC3: 2028-04 | AD3: 2028-05 | AE3: 2028-06 | AF3: 2028-07 | AG3: 2028-08 | AH3: 2028-09 | AI3: 2028-10 | AJ3: 2028-11 | AK3: 2028-12
A5: Sat（窓口/PM/ファシリ）
A6: 必要工数（時間） | B6: =('4_売上計画'!B$11*'2_プラン設計'!$B$8)+('4_売上計画'!B$12*'2_プラン設計'!$C$8)+('4_売上計画'!B$13*'2_プラン設計'!$D$8) | C6: =('4_売上計画'!C$11*'2_プラン設計'!$B$8)+('4_売上計画'!C$12*'2_プラン設計'!$C$8)+('4_売上計画'!C$13*'2_プラン設計'!$D$8) | D6: =('4_売上計画'!D$11*'2_プラン設計'!$B$8)+('4_売上計画'!D$12*'2_プラン設計'!$C$8)+('4_売上計画'!D$13*'2_プラン設計'!$D$8) | E6: =('4_売上計画'!E$11*'2_プラン設計'!$B$8)+('4_売上計画'!E$12*'2_プラン設計'!$C$8)+('4_売上計画'!E$13*'2_プラン設計'!$D$8) | F6: =('4_売上計画'!F$11*'2_プラン設計'!$B$8)+('4_売上計画'!F$12*'2_プラン設計'!$C$8)+('4_売上計画'!F$13*'2_プラン設計'!$D$8) | G6: =('4_売上計画'!G$11*'2_プラン設計'!$B$8)+('4_売上計画'!G$12*'2_プラン設計'!$C$8)+('4_売上計画'!G$13*'2_プラン設計'!$D$8) | H6: =('4_売上計画'!H$11*'2_プラン設計'!$B$8)+('4_売上計画'!H$12*'2_プラン設計'!$C$8)+('4_売上計画'!H$13*'2_プラン設計'!$D$8) | I6: =('4_売上計画'!I$11*'2_プラン設計'!$B$8)+('4_売上計画'!I$12*'2_プラン設計'!$C$8)+('4_売上計画'!I$13*'2_プラン設計'!$D$8) | ... AK6: =('4_売上計画'!AK$11*'2_プラン設計'!$B$8)+('4_売上計画'!AK$12*'2_プラン設計'!$C$8)+('4_売上計画'!AK$13*'2_プラン設計'!$D$8)
A7: 稼働上限（時間） | B7: =Sat_Cap | C7: =Sat_Cap | D7: =Sat_Cap | E7: =Sat_Cap | F7: =Sat_Cap | G7: =Sat_Cap | H7: =Sat_Cap | I7: =Sat_Cap | ... AK7: =Sat_Cap
A8: 稼働率 | B8: =IF(B$7=0,0,B$6/B$7) | C8: =IF(C$7=0,0,C$6/C$7) | D8: =IF(D$7=0,0,D$6/D$7) | E8: =IF(E$7=0,0,E$6/E$7) | F8: =IF(F$7=0,0,F$6/F$7) | G8: =IF(G$7=0,0,G$6/G$7) | H8: =IF(H$7=0,0,H$6/H$7) | I8: =IF(I$7=0,0,I$6/I$7) | ... AK8: =IF(AK$7=0,0,AK$6/AK$7)
A9: 超過（時間） | B9: =MAX(0,B$6-B$7) | C9: =MAX(0,C$6-C$7) | D9: =MAX(0,D$6-D$7) | E9: =MAX(0,E$6-E$7) | F9: =MAX(0,F$6-F$7) | G9: =MAX(0,G$6-G$7) | H9: =MAX(0,H$6-H$7) | I9: =MAX(0,I$6-I$7) | ... AK9: =MAX(0,AK$6-AK$7)
A11: Uni（インストラクター）
A12: 必要工数（時間） | B12: =('4_売上計画'!B$11*'2_プラン設計'!$B$9)+('4_売上計画'!B$12*'2_プラン設計'!$C$9)+('4_売上計画'!B$13*'2_プラン設計'!$D$9) | C12: =('4_売上計画'!C$11*'2_プラン設計'!$B$9)+('4_売上計画'!C$12*'2_プラン設計'!$C$9)+('4_売上計画'!C$13*'2_プラン設計'!$D$9) | D12: =('4_売上計画'!D$11*'2_プラン設計'!$B$9)+('4_売上計画'!D$12*'2_プラン設計'!$C$9)+('4_売上計画'!D$13*'2_プラン設計'!$D$9) | E12: =('4_売上計画'!E$11*'2_プラン設計'!$B$9)+('4_売上計画'!E$12*'2_プラン設計'!$C$9)+('4_売上計画'!E$13*'2_プラン設計'!$D$9) | F12: =('4_売上計画'!F$11*'2_プラン設計'!$B$9)+('4_売上計画'!F$12*'2_プラン設計'!$C$9)+('4_売上計画'!F$13*'2_プラン設計'!$D$9) | G12: =('4_売上計画'!G$11*'2_プラン設計'!$B$9)+('4_売上計画'!G$12*'2_プラン設計'!$C$9)+('4_売上計画'!G$13*'2_プラン設計'!$D$9) | H12: =('4_売上計画'!H$11*'2_プラン設計'!$B$9)+('4_売上計画'!H$12*'2_プラン設計'!$C$9)+('4_売上計画'!H$13*'2_プラン設計'!$D$9) | I12: =('4_売上計画'!I$11*'2_プラン設計'!$B$9)+('4_売上計画'!I$12*'2_プラン設計'!$C$9)+('4_売上計画'!I$13*'2_プラン設計'!$D$9) | ... AK12: =('4_売上計画'!AK$11*'2_プラン設計'!$B$9)+('4_売上計画'!AK$12*'2_プラン設計'!$C$9)+('4_売上計画'!AK$13*'2_プラン設計'!$D$9)
A13: 稼働上限（時間） | B13: =Uni_Cap | C13: =Uni_Cap | D13: =Uni_Cap | E13: =Uni_Cap | F13: =Uni_Cap | G13: =Uni_Cap | H13: =Uni_Cap | I13: =Uni_Cap | ... AK13: =Uni_Cap
A14: 稼働率 | B14: =IF(B$13=0,0,B$12/B$13) | C14: =IF(C$13=0,0,C$12/C$13) | D14: =IF(D$13=0,0,D$12/D$13) | E14: =IF(E$13=0,0,E$12/E$13) | F14: =IF(F$13=0,0,F$12/F$13) | G14: =IF(G$13=0,0,G$12/G$13) | H14: =IF(H$13=0,0,H$12/H$13) | I14: =IF(I$13=0,0,I$12/I$13) | ... AK14: =IF(AK$13=0,0,AK$12/AK$13)
A15: 超過（時間） | B15: =MAX(0,B$12-B$13) | C15: =MAX(0,C$12-C$13) | D15: =MAX(0,D$12-D$13) | E15: =MAX(0,E$12-E$13) | F15: =MAX(0,F$12-F$13) | G15: =MAX(0,G$12-G$13) | H15: =MAX(0,H$12-H$13) | I15: =MAX(0,I$12-I$13) | ... AK15: =MAX(0,AK$12-AK$13)
A17: Tim（設計/インストラクター）
A18: 必要工数（時間） | B18: =('4_売上計画'!B$11*'2_プラン設計'!$B$10)+('4_売上計画'!B$12*'2_プラン設計'!$C$10)+('4_売上計画'!B$13*'2_プラン設計'!$D$10) | C18: =('4_売上計画'!C$11*'2_プラン設計'!$B$10)+('4_売上計画'!C$12*'2_プラン設計'!$C$10)+('4_売上計画'!C$13*'2_プラン設計'!$D$10) | D18: =('4_売上計画'!D$11*'2_プラン設計'!$B$10)+('4_売上計画'!D$12*'2_プラン設計'!$C$10)+('4_売上計画'!D$13*'2_プラン設計'!$D$10) | E18: =('4_売上計画'!E$11*'2_プラン設計'!$B$10)+('4_売上計画'!E$12*'2_プラン設計'!$C$10)+('4_売上計画'!E$13*'2_プラン設計'!$D$10) | F18: =('4_売上計画'!F$11*'2_プラン設計'!$B$10)+('4_売上計画'!F$12*'2_プラン設計'!$C$10)+('4_売上計画'!F$13*'2_プラン設計'!$D$10) | G18: =('4_売上計画'!G$11*'2_プラン設計'!$B$10)+('4_売上計画'!G$12*'2_プラン設計'!$C$10)+('4_売上計画'!G$13*'2_プラン設計'!$D$10) | H18: =('4_売上計画'!H$11*'2_プラン設計'!$B$10)+('4_売上計画'!H$12*'2_プラン設計'!$C$10)+('4_売上計画'!H$13*'2_プラン設計'!$D$10) | I18: =('4_売上計画'!I$11*'2_プラン設計'!$B$10)+('4_売上計画'!I$12*'2_プラン設計'!$C$10)+('4_売上計画'!I$13*'2_プラン設計'!$D$10) | ... AK18: =('4_売上計画'!AK$11*'2_プラン設計'!$B$10)+('4_売上計画'!AK$12*'2_プラン設計'!$C$10)+('4_売上計画'!AK$13*'2_プラン設計'!$D$10)
A19: 稼働上限（時間） | B19: =Tim_Cap | C19: =Tim_Cap | D19: =Tim_Cap | E19: =Tim_Cap | F19: =Tim_Cap | G19: =Tim_Cap | H19: =Tim_Cap | I19: =Tim_Cap | ... AK19: =Tim_Cap
A20: 稼働率 | B20: =IF(B$19=0,0,B$18/B$19) | C20: =IF(C$19=0,0,C$18/C$19) | D20: =IF(D$19=0,0,D$18/D$19) | E20: =IF(E$19=0,0,E$18/E$19) | F20: =IF(F$19=0,0,F$18/F$19) | G20: =IF(G$19=0,0,G$18/G$19) | H20: =IF(H$19=0,0,H$18/H$19) | I20: =IF(I$19=0,0,I$18/I$19) | ... AK20: =IF(AK$19=0,0,AK$18/AK$19)
A21: 超過（時間） | B21: =MAX(0,B$18-B$19) | C21: =MAX(0,C$18-C$19) | D21: =MAX(0,D$18-D$19) | E21: =MAX(0,E$18-E$19) | F21: =MAX(0,F$18-F$19) | G21: =MAX(0,G$18-G$19) | H21: =MAX(0,H$18-H$19) | I21: =MAX(0,I$18-I$19) | ... AK21: =MAX(0,AK$18-AK$19)

Sheet 8_KPI
A1: KPIダッシュボード（年次サマリ）
A3: 指標 | B3: 2026 | C3: 2027 | E3: 解釈 / 目標の例
A4: 売上高 | B4: =SUM('4_売上計画'!B19:M19) | C4: =SUM('4_売上計画'!N19:Y19) | E4: 初年度は検証重視。2年目以降で単価×社数を伸ばす
A5: 原価 | B5: =SUM('5_原価・販管費'!B9:M9) | C5: =SUM('5_原価・販管費'!N9:Y9) | E5: 工数設計が甘いと膨らむ。プラン工数の見直しが最優先
A6: 粗利 | B6: =B4-B5 | C6: =C4-C5 | E6: 粗利が成長の原資。粗利率の改善は『テンプレ化』が効く
A7: 粗利率 | B7: =IF(B4=0,0,B6/B4) | C7: =IF(C4=0,0,C6/C4) | E7: 値引きより工数圧縮で改善
A8: 販管費 | B8: =SUM('5_原価・販管費'!B16:M16) | C8: =SUM('5_原価・販管費'!N16:Y16) | E8: 案件獲得あたりのマーケ費で管理
A9: EBITDA（概算） | B9: =B6-B8 | C9: =C6-C8 | E9: 黒字化タイミングと投資余力の指標
A10: 受注数（標準） | B10: =SUM('4_売上計画'!B7:M7) | C10: =SUM('4_売上計画'!N7:Y7) | E10: コア売上の積み上げ
A11: 受注数（ライトニング） | B11: =SUM('4_売上計画'!B8:M8) | C11: =SUM('4_売上計画'!N8:Y8) | E11: 高単価・短期。事例化の打率が重要
A12: 研修実施回数 | B12: =SUM('4_売上計画'!B9:M9) | C12: =SUM('4_売上計画'!N9:Y9) | E12: 入口（個人→企業）として使える
A13: ピーク稼働率 Sat | B13: =MAX('3_容量モデル'!B8:M8) | C13: =MAX('3_容量モデル'!N8:Y8) | E13: 80%超が続くなら採用/外注/工数削減を判断
A14: ピーク稼働率 Uni | B14: =MAX('3_容量モデル'!B14:M14) | C14: =MAX('3_容量モデル'!N14:Y14)
A15: ピーク稼働率 Tim | B15: =MAX('3_容量モデル'!B20:M20) | C15: =MAX('3_容量モデル'!N20:Y20)
A16: 年末現金残高（簡易） | B16: ='7_Cash'!M10 | C16: ='7_Cash'!Y10 | E16: 最悪ケースでもマイナスにしない

Sheet 10_営業ファネル
A1: 営業ファネル（月次目安）— 受注数から逆算して必要リード数を出す
A3: 項目 | B3: 2026-01 | C3: 2026-02 | D3: 2026-03 | E3: 2026-04 | F3: 2026-05 | G3: 2026-06 | H3: 2026-07 | I3: 2026-08 | J3: 2026-09 | K3: 2026-10 | L3: 2026-11 | M3: 2026-12 | N3: 2027-01 | O3: 2027-02 | P3: 2027-03 | Q3: 2027-04 | R3: 2027-05 | S3: 2027-06 | T3: 2027-07 | U3: 2027-08 | V3: 2027-09 | W3: 2027-10 | X3: 2027-11 | Y3: 2027-12 | Z3: 2028-01 | AA3: 2028-02 | AB3: 2028-03 | AC3: 2028-04 | AD3: 2028-05 | AE3: 2028-06 | AF3: 2028-07 | AG3: 2028-08 | AH3: 2028-09 | AI3: 2028-10 | AJ3: 2028-11 | AK3: 2028-12
A5: 受注数（合計） | B5: ='4_売上計画'!B$7+'4_売上計画'!B$8+'4_売上計画'!B$9 | C5: ='4_売上計画'!C$7+'4_売上計画'!C$8+'4_売上計画'!C$9 | D5: ='4_売上計画'!D$7+'4_売上計画'!D$8+'4_売上計画'!D$9 | E5: ='4_売上計画'!E$7+'4_売上計画'!E$8+'4_売上計画'!E$9 | F5: ='4_売上計画'!F$7+'4_売上計画'!F$8+'4_売上計画'!F$9 | G5: ='4_売上計画'!G$7+'4_売上計画'!G$8+'4_売上計画'!G$9 | H5: ='4_売上計画'!H$7+'4_売上計画'!H$8+'4_売上計画'!H$9 | I5: ='4_売上計画'!I$7+'4_売上計画'!I$8+'4_売上計画'!I$9 | ... AK5: ='4_売上計画'!AK$7+'4_売上計画'!AK$8+'4_売上計画'!AK$9
A6: 提案数（必要） | B6: =IF('1_前提'!$B$37=0,0,B$5/'1_前提'!$B$37) | C6: =IF('1_前提'!$B$37=0,0,C$5/'1_前提'!$B$37) | D6: =IF('1_前提'!$B$37=0,0,D$5/'1_前提'!$B$37) | E6: =IF('1_前提'!$B$37=0,0,E$5/'1_前提'!$B$37) | F6: =IF('1_前提'!$B$37=0,0,F$5/'1_前提'!$B$37) | G6: =IF('1_前提'!$B$37=0,0,G$5/'1_前提'!$B$37) | H6: =IF('1_前提'!$B$37=0,0,H$5/'1_前提'!$B$37) | I6: =IF('1_前提'!$B$37=0,0,I$5/'1_前提'!$B$37) | ... AK6: =IF('1_前提'!$B$37=0,0,AK$5/'1_前提'!$B$37)
A7: 初回相談数（必要） | B7: =IF('1_前提'!$B$36=0,0,B$6/'1_前提'!$B$36) | C7: =IF('1_前提'!$B$36=0,0,C$6/'1_前提'!$B$36) | D7: =IF('1_前提'!$B$36=0,0,D$6/'1_前提'!$B$36) | E7: =IF('1_前提'!$B$36=0,0,E$6/'1_前提'!$B$36) | F7: =IF('1_前提'!$B$36=0,0,F$6/'1_前提'!$B$36) | G7: =IF('1_前提'!$B$36=0,0,G$6/'1_前提'!$B$36) | H7: =IF('1_前提'!$B$36=0,0,H$6/'1_前提'!$B$36) | I7: =IF('1_前提'!$B$36=0,0,I$6/'1_前提'!$B$36) | ... AK7: =IF('1_前提'!$B$36=0,0,AK$6/'1_前提'!$B$36)
A8: リード数（必要） | B8: =IF('1_前提'!$B$35=0,0,B$7/'1_前提'!$B$35) | C8: =IF('1_前提'!$B$35=0,0,C$7/'1_前提'!$B$35) | D8: =IF('1_前提'!$B$35=0,0,D$7/'1_前提'!$B$35) | E8: =IF('1_前提'!$B$35=0,0,E$7/'1_前提'!$B$35) | F8: =IF('1_前提'!$B$35=0,0,F$7/'1_前提'!$B$35) | G8: =IF('1_前提'!$B$35=0,0,G$7/'1_前提'!$B$35) | H8: =IF('1_前提'!$B$35=0,0,H$7/'1_前提'!$B$35) | I8: =IF('1_前提'!$B$35=0,0,I$7/'1_前提'!$B$35) | ... AK8: =IF('1_前提'!$B$35=0,0,AK$7/'1_前提'!$B$35)
A10: メモ | B10: 1_前提の『リード→初回相談』『初回相談→提案』『提案→受注』の率で逆算。受注目標を置いた後に、施策（ウェビナー/紹介/コンテンツ/SNS）を設計。

Sheet 11_実行計画
A1: 実行計画（用意するもの・優先度）
A3: 成果物/仕組み | B3: オーナー | C3: 期限（目安） | D3: 狙い（事業計画に効く理由）
A4: LP（AIチーム開発を前面） | B4: Sat | C4: 2週間 | D4: 問い合わせ獲得。ライトニング/標準/研修の3プラン比較を1ページに集約
A5: 提案書テンプレ（課題→ToBe→設計→見積） | B5: Sat | C5: 2週間 | D5: 提案速度を上げ、値引き交渉を減らす
A6: 契約/約款（成果物・範囲・免責） | B6: Sat | C6: 3週間 | D6: スコープ事故を防ぐ。支払い条件を明確化
A7: カリキュラム（補助金対応版） | B7: Uni/Tim | C7: 3週間 | D7: 助成金活用のフックを作る（提出物・出席・証明）
A8: 運用SOP（MTG→課題→実装→振り返り） | B8: Uni/Tim | C8: 4週間 | D8: 工数を圧縮し粗利率を上げる。属人性を減らす
A9: ケーススタディ2本（数字付き） | B9: Sat+Uni/Tim | C9: 6週間 | D9: 受注率を押し上げる（営業ファネルの改善）
A10: プロジェクト管理（Notion等） | B10: Sat | C10: 1週間 | D10: 並走案件数が増えても破綻しない
A11: 品質指標（NPS/完了率/定着率） | B11: Uni/Tim | C11: 4週間 | D11: 継続/紹介の源泉。LTVを伸ばす
A12: 外注ネットワーク（必要時の増員） | B12: Tim | C12: 6週間 | D12: 稼働超過リスクへの備え（容量モデルの警告に対応）

Sheet 9_感度
A1: 感度分析（シナリオ倍率の置き場）
A3: 使い方：ここで倍率を決め、1_前提の『シナリオ』を切り替えて検討材料にする。現状のモデルは新規契約数を手入力するため、倍率は主に『目標逆算』『議論のたたき台』用途。
A5: シナリオ | B5: 売価倍率 | C5: 新規獲得倍率 | D5: 工数倍率 | E5: メモ
A6: 1 | B6: 0.9 | C6: 0.7 | D6: 1.1 | E6: 保守：値引き/獲得難/工数増（立ち上げ期のブレを織り込む）
A7: 2 | B7: 1 | C7: 1 | D7: 1 | E7: 標準：現状の仮説（ベースケース）
A8: 3 | B8: 1.05 | C8: 1.3 | D8: 0.9 | E8: 攻め：事例が刺さり獲得加速/テンプレ化で工数圧縮

Sheet 12_BS
A1: 貸借対照表（BS）月次（簡易）
A2: ※入金スケジュールと収益認識の差分から、未収（A/R）と前受（繰延収益）を簡易推計。税金/減価償却等は未考慮。
A4: 項目 | B4: 2026-01 | C4: 2026-02 | D4: 2026-03 | E4: 2026-04 | F4: 2026-05 | G4: 2026-06 | H4: 2026-07 | I4: 2026-08 | J4: 2026-09 | K4: 2026-10 | L4: 2026-11 | M4: 2026-12 | N4: 2027-01 | O4: 2027-02 | P4: 2027-03 | Q4: 2027-04 | R4: 2027-05 | S4: 2027-06 | T4: 2027-07 | U4: 2027-08 | V4: 2027-09 | W4: 2027-10 | X4: 2027-11 | Y4: 2027-12
A5: 資産
A6: 現金 | B6: ='7_Cash'!B10 | C6: ='7_Cash'!C10 | D6: ='7_Cash'!D10 | E6: ='7_Cash'!E10 | F6: ='7_Cash'!F10 | G6: ='7_Cash'!G10 | H6: ='7_Cash'!H10 | I6: ='7_Cash'!I10 | ... Y6: ='7_Cash'!Y10
A7: 売掛金（未収） | B7: =MAX(B23,0) | C7: =MAX(C23,0) | D7: =MAX(D23,0) | E7: =MAX(E23,0) | F7: =MAX(F23,0) | G7: =MAX(G23,0) | H7: =MAX(H23,0) | I7: =MAX(I23,0) | ... Y7: =MAX(Y23,0)
A8: 資産合計 | B8: =B6+B7 | C8: =C6+C7 | D8: =D6+D7 | E8: =E6+E7 | F8: =F6+F7 | G8: =G6+G7 | H8: =H6+H7 | I8: =I6+I7 | ... Y8: =Y6+Y7
A10: 負債
A11: 繰延収益（前受） | B11: =MAX(-B23,0) | C11: =MAX(-C23,0) | D11: =MAX(-D23,0) | E11: =MAX(-E23,0) | F11: =MAX(-F23,0) | G11: =MAX(-G23,0) | H11: =MAX(-H23,0) | I11: =MAX(-I23,0) | ... Y11: =MAX(-Y23,0)
A12: 負債合計 | B12: =B11 | C12: =C11 | D12: =D11 | E12: =E11 | F12: =F11 | G12: =G11 | H12: =H11 | I12: =I11 | ... Y12: =Y11
A14: 純資産
A15: 資本金（初期現金） | B15: ='7_Cash'!$B$3 | C15: ='7_Cash'!$B$3 | D15: ='7_Cash'!$B$3 | E15: ='7_Cash'!$B$3 | F15: ='7_Cash'!$B$3 | G15: ='7_Cash'!$B$3 | H15: ='7_Cash'!$B$3 | I15: ='7_Cash'!$B$3 | ... Y15: ='7_Cash'!$B$3
A16: 利益剰余金（累計：EBITDAベース） | B16: =B24 | C16: =C24 | D16: =D24 | E16: =E24 | F16: =F24 | G16: =G24 | H16: =H24 | I16: =I24 | ... Y16: =Y24
A17: 純資産合計 | B17: =B15+B16 | C17: =C15+C16 | D17: =D15+D16 | E17: =E15+E16 | F17: =F15+F16 | G17: =G15+G16 | H17: =H15+H16 | I17: =I15+I16 | ... Y17: =Y15+Y16
A19: 差額チェック（資産-負債-純資産） | B19: =B8-B12-B17 | C19: =C8-C12-C17 | D19: =D8-D12-D17 | E19: =E8-E12-E17 | F19: =F8-F12-F17 | G19: =G8-G12-G17 | H19: =H8-H12-H17 | I19: =I8-I12-I17 | ... Y19: =Y8-Y12-Y17
A22: 補助計算
A23: 累計差分（収益-入金） | B23: =('4_売上計画'!B19-'4_売上計画'!B25) | C23: =B23+('4_売上計画'!C19-'4_売上計画'!C25) | D23: =C23+('4_売上計画'!D19-'4_売上計画'!D25) | E23: =D23+('4_売上計画'!E19-'4_売上計画'!E25) | F23: =E23+('4_売上計画'!F19-'4_売上計画'!F25) | G23: =F23+('4_売上計画'!G19-'4_売上計画'!G25) | H23: =G23+('4_売上計画'!H19-'4_売上計画'!H25) | I23: =H23+('4_売上計画'!I19-'4_売上計画'!I25) | J23: =I23+('4_売上計画'!J19-'4_売上計画'!J25) | ... Y23: =X23+('4_売上計画'!Y19-'4_売上計画'!Y25)
A24: 累計EBITDA（P&L） | B24: ='6_P&L'!B10 | C24: =B24+'6_P&L'!C10 | D24: =C24+'6_P&L'!D10 | E24: =D24+'6_P&L'!E10 | F24: =E24+'6_P&L'!F10 | G24: =F24+'6_P&L'!G10 | H24: =G24+'6_P&L'!H10 | I24: =H24+'6_P&L'!I10 | J24: =I24+'6_P&L'!J10 | ... Y24: =X24+'6_P&L'!Y10
